Workbook

Sheet RETAIL SALES DATA.
A1: Order_ID | B1: Customer_Name | C1: Product_Name | D1: Product_Category | E1: Region | F1: Sales_Quantity | G1: Unit_Price | H1: Sales_Amount | I1: Cost | J1: Profit | K1: Order_Date | L1: Delivery_Date | M1: Employee_Name | N1: Customer_Rating | O1: Login_Time | P1: Working_Hours
A2: ORD0001 | B2: Michael Winters | C2: Pen | D2: Office Supplies | E2: South | F2: 4 | G2: 1578.68 | H2: 6314.72 | I2: 4409.14 | J2: 1905.58 | K2: 45913 | L2: 45922 | M2: Rahul | N2: 5 | O2: 10:12:00 | P2: 8.9
A3: ORD0002 | B3: James Olson | C3: Pen | D3: Office Supplies | E3: North | F3: 18 | G3: 1427.85 | H3: 25701.3 | I3: 15663.81 | J3: 10037.49 | K3: 46023 | L3: 46026 | M3: Megha | N3: 1 | O3: 08:15:00 | P3: 8.6
A4: ORD0003 | B4: Brittney Simmons | C4: Desk | D4: Furniture | E4: West | F4: 18 | G4: 3667.53 | H4: 66015.54 | I4: 41337.25 | J4: 24678.29 | K4: 46152 | L4: 46161 | M4: Arun | N4: 5 | O4: 11:33:00 | P4: 7.3
A5: ORD0004 | B5: Courtney Park | C5: Marker | D5: Office Supplies | E5: North | F5: 1 | G5: 3550.31 | H5: 3550.31 | I5: 2061.79 | J5: 1488.52 | K5: 45483 | L5: 45491 | M5: Vivek | N5: 4 | O5: 11:19:00 | P5: 6.5
A6: ORD0005 | B6: Chloe Villa | C6: Laptop | D6: Electronics | E6: East | F6: 13 | G6: 1838.36 | H6: 23898.68 | I6: 17283.83 | J6: 6614.85 | K6: 46052 | L6: 46062 | M6: Diya | N6: 1 | O6: 10:02:00 | P6: 8.7
A7: ORD0006 | B7: Erin Ross | C7: Mouse | D7: Electronics | E7: West | F7: 1 | G7: 4093.77 | H7: 4093.77 | I7: 2721.22 | J7: 1372.55 | K7: 45502 | L7: 45505 | M7: Fathima | N7: 1 | O7: 09:28:00 | P7: 8.6
A8: ORD0007 | B8: Ryan Brown | C8: Laptop | D8: Electronics | E8: West | F8: 17 | G8: 2540.86 | H8: 43194.62 | I8: 22584.56 | J8: 20610.06 | K8: 45494 | L8: 45498 | M8: Rahul | N8: 1 | O8: 08:18:00 | P8: 8.9
A9: ORD0008 | B9: Keith Winters | C9: Notebook | D9: Office Supplies | E9: East | F9: 12 | G9: 4957.92 | H9: 59495.04 | I9: 49409.66 | J9: 10085.38 | K9: 46147 | L9: 46150 | M9: Sneha | N9: 2 | O9: 09:04:00 | P9: 8
A10: ORD0009 | B10: Richard Payne | C10: Table | D10: Furniture | E10: East | F10: 2 | G10: 3280.82 | H10: 6561.64 | I10: 5871.1 | J10: 690.54 | K10: 45607 | L10: 45610 | M10: Vivek | N10: 1 | O10: 11:17:00 | P10: 6.6
A11: ORD0010 | B11: Cory Roberson | C11: Pen | D11: Office Supplies | E11: North | F11: 14 | G11: 1988.47 | H11: 27838.58 | I11: 19080.73 | J11: 8757.85 | K11: 45712 | L11: 45716 | M11: Rahul | N11: 2 | O11: 11:14:00 | P11: 9.4
A12: ORD0011 | B12: Amanda Cox | C12: Desk | D12: Furniture | E12: North | F12: 15 | G12: 991.66 | H12: 14874.9 | I12: 11249.49 | J12: 3625.41 | K12: 45628 | L12: 45634 | M12: Akhil | N12: 5 | O12: 11:14:00 | P12: 9.5
A13: ORD0012 | B13: Joseph Allison | C13: Chair | D13: Furniture | E13: South | F13: 12 | G13: 4247.3 | H13: 50967.6 | I13: 39899.98 | J13: 11067.62 | K13: 45786 | L13: 45795 | M13: Sneha | N13: 3 | O13: 11:34:00 | P13: 6.8
... A1001: ORD1000 | B1001: Matthew Bradley | C1001: Cupboard | D1001: Furniture | E1001: West | F1001: 16 | G1001: 3752.49 | H1001: 60039.84 | I1001: 36366.23 | J1001: 23673.61 | K1001: 45821 | L1001: 45827 | M1001: Diya | N1001: 4 | O1001: 11:29:00 | P1001: 6.4

Sheet Unique Details
B1: =COUNTA(_xlfn.ANCHORARRAY(B3)) -> 992 | C1: =COUNTA(_xlfn.ANCHORARRAY(C3)) -> 15 | D1: =COUNTA(_xlfn.ANCHORARRAY(D3)) -> 3 | E1: =COUNTA(_xlfn.ANCHORARRAY(E3)) -> 4 | F1: =COUNTA(_xlfn.ANCHORARRAY(F3)) -> 10
B2: Customer Name | C2: Unique Product | D2: Unique Product category | E2: Unique Region | F2: Unique Empolyee
B3: {=_xlfn.UNIQUE('RETAIL SALES DATA.'!$B$2:$B$1001)} -> Michael Winters | C3: {=_xlfn.UNIQUE('RETAIL SALES DATA.'!$C$2:$C$1001)} -> Pen | D3: {=_xlfn.UNIQUE('RETAIL SALES DATA.'!$D$2:$D$1001)} -> Office Supplies | E3: {=_xlfn.UNIQUE('RETAIL SALES DATA.'!$E$2:$E$1001)} -> South | F3: {=_xlfn.UNIQUE('RETAIL SALES DATA.'!$M$2:$M$1001)} -> Rahul
B4: James Olson | C4: Desk | D4: Furniture | E4: North | F4: Megha
B5: Brittney Simmons | C5: Marker | D5: Electronics | E5: West | F5: Arun
B6: Courtney Park | C6: Laptop | E6: East | F6: Vivek
B7: Chloe Villa | C7: Mouse | F7: Diya
B8: Erin Ross | C8: Notebook | F8: Fathima
B9: Ryan Brown | C9: Table | F9: Sneha
B10: Keith Winters | C10: Chair | F10: Akhil
B11: Richard Payne | C11: Cupboard | F11: Nikhil
B12: Cory Roberson | C12: Printer | F12: Anjali
B13: Amanda Cox | C13: Sofa
B14: Joseph Allison | C14: File
B15: Sarah Hernandez | C15: Keyboard
B16: John Dixon | C16: Monitor
B17: Javier Cole | C17: Smartphone
B18: Nathan Kline
B19: Miss Christina Taylor
B20: Martin Morton
B21: Adam Mullins
B22: Sean Rodriguez
B23: Joseph Mora
B24: Deborah Hernandez
B25: Elizabeth Moore
B26: Melissa Davis
B27: Andrew Gould
B28: Glen Scott
B29: Isaac Fisher
... B994: Matthew Bradley

Sheet Findings
B2: Items | C2: Category | D2: Overalll Sales | E2: Total Qutantity | F2: Total Cost | G2: Total Profit | H2: Average Sales | I2: Average Profit | J2: Avg Qty Sold
B3: {=_xlfn.UNIQUE('RETAIL SALES DATA.'!$C$2:$C$1001)} -> Pen | C3: Office Supplies | D3: =SUMIF('RETAIL SALES DATA.'!$C$2:$C$1001,Findings!B3,'RETAIL SALES DATA.'!$H$2:$H$1001) -> 1451635.9 | E3: =COUNTIF('RETAIL SALES DATA.'!$C$2:$C$1001,Findings!B3) -> 59 | F3: =SUMIFS('RETAIL SALES DATA.'!$I$2:$I$1001,'RETAIL SALES DATA.'!$C$2:$C$1001,Findings!B3) -> 1012285.4 | G3: =SUMIFS('RETAIL SALES DATA.'!$J$2:$J$1001,'RETAIL SALES DATA.'!$C$2:$C$1001,Findings!B3) -> 439350.43 | H3: =AVERAGEIF('RETAIL SALES DATA.'!$C$2:$C$1001,Findings!B3,'RETAIL SALES DATA.'!$H$2:$H$1001) -> 24603.997 | I3: =AVERAGEIF('RETAIL SALES DATA.'!$C$2:$C$1001,Findings!B3,'RETAIL SALES DATA.'!$J$2:$J$1001) -> 7446.6175 | J3: =AVERAGEIF('RETAIL SALES DATA.'!$C$2:$C$1001,Findings!B3,'RETAIL SALES DATA.'!$F$2:$F$1001) -> 10.728814
B4: Desk | C4: Furniture | D4: =SUMIF('RETAIL SALES DATA.'!$C$2:$C$1001,Findings!B4,'RETAIL SALES DATA.'!$H$2:$H$1001) -> 2145826.9 | E4: =COUNTIF('RETAIL SALES DATA.'!$C$2:$C$1001,Findings!B4) -> 79 | F4: =SUMIFS('RETAIL SALES DATA.'!$I$2:$I$1001,'RETAIL SALES DATA.'!$C$2:$C$1001,Findings!B4) -> 1445133.3 | G4: =SUMIFS('RETAIL SALES DATA.'!$J$2:$J$1001,'RETAIL SALES DATA.'!$C$2:$C$1001,Findings!B4) -> 700693.65 | H4: =AVERAGEIF('RETAIL SALES DATA.'!$C$2:$C$1001,Findings!B4,'RETAIL SALES DATA.'!$H$2:$H$1001) -> 27162.366 | I4: =AVERAGEIF('RETAIL SALES DATA.'!$C$2:$C$1001,Findings!B4,'RETAIL SALES DATA.'!$J$2:$J$1001) -> 8869.5399 | J4: =AVERAGEIF('RETAIL SALES DATA.'!$C$2:$C$1001,Findings!B4,'RETAIL SALES DATA.'!$F$2:$F$1001) -> 10.873418
B5: Marker | C5: Office Supplies | D5: =SUMIF('RETAIL SALES DATA.'!$C$2:$C$1001,Findings!B5,'RETAIL SALES DATA.'!$H$2:$H$1001) -> 1522379.9 | E5: =COUNTIF('RETAIL SALES DATA.'!$C$2:$C$1001,Findings!B5) -> 55 | F5: =SUMIFS('RETAIL SALES DATA.'!$I$2:$I$1001,'RETAIL SALES DATA.'!$C$2:$C$1001,Findings!B5) -> 1052401.5 | G5: =SUMIFS('RETAIL SALES DATA.'!$J$2:$J$1001,'RETAIL SALES DATA.'!$C$2:$C$1001,Findings!B5) -> 469978.42 | H5: =AVERAGEIF('RETAIL SALES DATA.'!$C$2:$C$1001,Findings!B5,'RETAIL SALES DATA.'!$H$2:$H$1001) -> 27679.634 | I5: =AVERAGEIF('RETAIL SALES DATA.'!$C$2:$C$1001,Findings!B5,'RETAIL SALES DATA.'!$J$2:$J$1001) -> 8545.0622 | J5: =AVERAGEIF('RETAIL SALES DATA.'!$C$2:$C$1001,Findings!B5,'RETAIL SALES DATA.'!$F$2:$F$1001) -> 10.727273
B6: Laptop | C6: Electronics | D6: =SUMIF('RETAIL SALES DATA.'!$C$2:$C$1001,Findings!B6,'RETAIL SALES DATA.'!$H$2:$H$1001) -> 1776611.3 | E6: =COUNTIF('RETAIL SALES DATA.'!$C$2:$C$1001,Findings!B6) -> 70 | F6: =SUMIFS('RETAIL SALES DATA.'!$I$2:$I$1001,'RETAIL SALES DATA.'!$C$2:$C$1001,Findings!B6) -> 1267537.9 | G6: =SUMIFS('RETAIL SALES DATA.'!$J$2:$J$1001,'RETAIL SALES DATA.'!$C$2:$C$1001,Findings!B6) -> 509073.39 | H6: =AVERAGEIF('RETAIL SALES DATA.'!$C$2:$C$1001,Findings!B6,'RETAIL SALES DATA.'!$H$2:$H$1001) -> 25380.162 | I6: =AVERAGEIF('RETAIL SALES DATA.'!$C$2:$C$1001,Findings!B6,'RETAIL SALES DATA.'!$J$2:$J$1001) -> 7272.477 | J6: =AVERAGEIF('RETAIL SALES DATA.'!$C$2:$C$1001,Findings!B6,'RETAIL SALES DATA.'!$F$2:$F$1001) -> 9.8714286
B7: Mouse | C7: Electronics | D7: =SUMIF('RETAIL SALES DATA.'!$C$2:$C$1001,Findings!B7,'RETAIL SALES DATA.'!$H$2:$H$1001) -> 1857757.4 | E7: =COUNTIF('RETAIL SALES DATA.'!$C$2:$C$1001,Findings!B7) -> 74 | F7: =SUMIFS('RETAIL SALES DATA.'!$I$2:$I$1001,'RETAIL SALES DATA.'!$C$2:$C$1001,Findings!B7) -> 1339072.7 | G7: =SUMIFS('RETAIL SALES DATA.'!$J$2:$J$1001,'RETAIL SALES DATA.'!$C$2:$C$1001,Findings!B7) -> 518684.66 | H7: =AVERAGEIF('RETAIL SALES DATA.'!$C$2:$C$1001,Findings!B7,'RETAIL SALES DATA.'!$H$2:$H$1001) -> 25104.83 | I7: =AVERAGEIF('RETAIL SALES DATA.'!$C$2:$C$1001,Findings!B7,'RETAIL SALES DATA.'!$J$2:$J$1001) -> 7009.2522 | J7: =AVERAGEIF('RETAIL SALES DATA.'!$C$2:$C$1001,Findings!B7,'RETAIL SALES DATA.'!$F$2:$F$1001) -> 10.094595 | L7: Region | M7: Office Supplies | N7: Furniture | O7: Electronics | P7: Max | Q7: Min
B8: Notebook | C8: Office Supplies | D8: =SUMIF('RETAIL SALES DATA.'!$C$2:$C$1001,Findings!B8,'RETAIL SALES DATA.'!$H$2:$H$1001) -> 1538795.5 | E8: =COUNTIF('RETAIL SALES DATA.'!$C$2:$C$1001,Findings!B8) -> 61 | F8: =SUMIFS('RETAIL SALES DATA.'!$I$2:$I$1001,'RETAIL SALES DATA.'!$C$2:$C$1001,Findings!B8) -> 1074770.4 | G8: =SUMIFS('RETAIL SALES DATA.'!$J$2:$J$1001,'RETAIL SALES DATA.'!$C$2:$C$1001,Findings!B8) -> 464025.08 | H8: =AVERAGEIF('RETAIL SALES DATA.'!$C$2:$C$1001,Findings!B8,'RETAIL SALES DATA.'!$H$2:$H$1001) -> 25226.156 | I8: =AVERAGEIF('RETAIL SALES DATA.'!$C$2:$C$1001,Findings!B8,'RETAIL SALES DATA.'!$J$2:$J$1001) -> 7606.9685 | J8: =AVERAGEIF('RETAIL SALES DATA.'!$C$2:$C$1001,Findings!B8,'RETAIL SALES DATA.'!$F$2:$F$1001) -> 10.409836 | L8: South | M8: =SUMIFS('RETAIL SALES DATA.'!$H$2:$H$1001,'RETAIL SALES DATA.'!$E$2:$E$1001,'RETAIL SALES DATA.'!E2,'RETAIL SALES DATA.'!$D$2:$D$1001,'RETAIL SALES DATA.'!D2) -> 2140165 | N8: =SUMIFS('RETAIL SALES DATA.'!$H$2:$H$1001,'RETAIL SALES DATA.'!$E$2:$E$1001,'RETAIL SALES DATA.'!E2,'RETAIL SALES DATA.'!$D$2:$D$1001,'RETAIL SALES DATA.'!D4) -> 2077898.5 | O8: =SUMIFS('RETAIL SALES DATA.'!$H$2:$H$1001,'RETAIL SALES DATA.'!$E$2:$E$1001,'RETAIL SALES DATA.'!E2,'RETAIL SALES DATA.'!$D$2:$D$1001,'RETAIL SALES DATA.'!D6) -> 1750133 | P8: =MAX(M8:O8) -> 2140165 | Q8: =MIN(M8:P8) -> 1750133
B9: Table | C9: Furniture | D9: =SUMIF('RETAIL SALES DATA.'!$C$2:$C$1001,Findings!B9,'RETAIL SALES DATA.'!$H$2:$H$1001) -> 1725285.4 | E9: =COUNTIF('RETAIL SALES DATA.'!$C$2:$C$1001,Findings!B9) -> 73 | F9: =SUMIFS('RETAIL SALES DATA.'!$I$2:$I$1001,'RETAIL SALES DATA.'!$C$2:$C$1001,Findings!B9) -> 1181110.4 | G9: =SUMIFS('RETAIL SALES DATA.'!$J$2:$J$1001,'RETAIL SALES DATA.'!$C$2:$C$1001,Findings!B9) -> 544175 | H9: =AVERAGEIF('RETAIL SALES DATA.'!$C$2:$C$1001,Findings!B9,'RETAIL SALES DATA.'!$H$2:$H$1001) -> 23634.047 | I9: =AVERAGEIF('RETAIL SALES DATA.'!$C$2:$C$1001,Findings!B9,'RETAIL SALES DATA.'!$J$2:$J$1001) -> 7454.4521 | J9: =AVERAGEIF('RETAIL SALES DATA.'!$C$2:$C$1001,Findings!B9,'RETAIL SALES DATA.'!$F$2:$F$1001) -> 9.4246575 | L9: North | M9: =SUMIFS('RETAIL SALES DATA.'!$H$2:$H$1001,'RETAIL SALES DATA.'!$E$2:$E$1001,'RETAIL SALES DATA.'!E4,'RETAIL SALES DATA.'!$D$2:$D$1001,'RETAIL SALES DATA.'!D3) -> 2366969.2 | N9: =SUMIFS('RETAIL SALES DATA.'!$H$2:$H$1001,'RETAIL SALES DATA.'!$E$2:$E$1001,'RETAIL SALES DATA.'!E3,'RETAIL SALES DATA.'!$D$2:$D$1001,'RETAIL SALES DATA.'!D4) -> 2197906.7 | O9: =SUMIFS('RETAIL SALES DATA.'!$H$2:$H$1001,'RETAIL SALES DATA.'!$E$2:$E$1001,'RETAIL SALES DATA.'!E3,'RETAIL SALES DATA.'!$D$2:$D$1001,'RETAIL SALES DATA.'!D7) -> 2029227 | P9: =MAX(M9:O9) -> 2366969.2 | Q9: =MIN(M9:P9) -> 2029227
B10: Chair | C10: Furniture | D10: =SUMIF('RETAIL SALES DATA.'!$C$2:$C$1001,Findings!B10,'RETAIL SALES DATA.'!$H$2:$H$1001) -> 1896807.1 | E10: =COUNTIF('RETAIL SALES DATA.'!$C$2:$C$1001,Findings!B10) -> 68 | F10: =SUMIFS('RETAIL SALES DATA.'!$I$2:$I$1001,'RETAIL SALES DATA.'!$C$2:$C$1001,Findings!B10) -> 1259143.1 | G10: =SUMIFS('RETAIL SALES DATA.'!$J$2:$J$1001,'RETAIL SALES DATA.'!$C$2:$C$1001,Findings!B10) -> 637663.99 | H10: =AVERAGEIF('RETAIL SALES DATA.'!$C$2:$C$1001,Findings!B10,'RETAIL SALES DATA.'!$H$2:$H$1001) -> 27894.222 | I10: =AVERAGEIF('RETAIL SALES DATA.'!$C$2:$C$1001,Findings!B10,'RETAIL SALES DATA.'!$J$2:$J$1001) -> 9377.4116 | J10: =AVERAGEIF('RETAIL SALES DATA.'!$C$2:$C$1001,Findings!B10,'RETAIL SALES DATA.'!$F$2:$F$1001) -> 11.294118 | L10: West | M10: =SUMIFS('RETAIL SALES DATA.'!$H$2:$H$1001,'RETAIL SALES DATA.'!$E$2:$E$1001,'RETAIL SALES DATA.'!E4,'RETAIL SALES DATA.'!$D$2:$D$1001,'RETAIL SALES DATA.'!D4) -> 2785048.3 | N10: =SUMIFS('RETAIL SALES DATA.'!$H$2:$H$1001,'RETAIL SALES DATA.'!$E$2:$E$1001,'RETAIL SALES DATA.'!E4,'RETAIL SALES DATA.'!$D$2:$D$1001,'RETAIL SALES DATA.'!D4) -> 2785048.3 | O10: =SUMIFS('RETAIL SALES DATA.'!$H$2:$H$1001,'RETAIL SALES DATA.'!$E$2:$E$1001,'RETAIL SALES DATA.'!E4,'RETAIL SALES DATA.'!$D$2:$D$1001,'RETAIL SALES DATA.'!D8) -> 2536765.1 | P10: =MAX(M10:O10) -> 2785048.3 | Q10: =MIN(M10:P10) -> 2536765.1
B11: Cupboard | C11: Furniture | D11: =SUMIF('RETAIL SALES DATA.'!$C$2:$C$1001,Findings!B11,'RETAIL SALES DATA.'!$H$2:$H$1001) -> 1946675.6 | E11: =COUNTIF('RETAIL SALES DATA.'!$C$2:$C$1001,Findings!B11) -> 68 | F11: =SUMIFS('RETAIL SALES DATA.'!$I$2:$I$1001,'RETAIL SALES DATA.'!$C$2:$C$1001,Findings!B11) -> 1348687.1 | G11: =SUMIFS('RETAIL SALES DATA.'!$J$2:$J$1001,'RETAIL SALES DATA.'!$C$2:$C$1001,Findings!B11) -> 597988.46 | H11: =AVERAGEIF('RETAIL SALES DATA.'!$C$2:$C$1001,Findings!B11,'RETAIL SALES DATA.'!$H$2:$H$1001) -> 28627.582 | I11: =AVERAGEIF('RETAIL SALES DATA.'!$C$2:$C$1001,Findings!B11,'RETAIL SALES DATA.'!$J$2:$J$1001) -> 8793.9479 | J11: =AVERAGEIF('RETAIL SALES DATA.'!$C$2:$C$1001,Findings!B11,'RETAIL SALES DATA.'!$F$2:$F$1001) -> 9.8823529 | L11: East | M11: =SUMIFS('RETAIL SALES DATA.'!$H$2:$H$1001,'RETAIL SALES DATA.'!$E$2:$E$1001,'RETAIL SALES DATA.'!E6,'RETAIL SALES DATA.'!$D$2:$D$1001,'RETAIL SALES DATA.'!D5) -> 1770495.3 | N11: =SUMIFS('RETAIL SALES DATA.'!$H$2:$H$1001,'RETAIL SALES DATA.'!$E$2:$E$1001,'RETAIL SALES DATA.'!E6,'RETAIL SALES DATA.'!$D$2:$D$1001,'RETAIL SALES DATA.'!D4) -> 2244148.8 | O11: =SUMIFS('RETAIL SALES DATA.'!$H$2:$H$1001,'RETAIL SALES DATA.'!$E$2:$E$1001,'RETAIL SALES DATA.'!E6,'RETAIL SALES DATA.'!$D$2:$D$1001,'RETAIL SALES DATA.'!D6) -> 2145539.5 | P11: =MAX(M11:O11) -> 2244148.8 | Q11: =MIN(M11:P11) -> 1770495.3
B12: Printer | C12: Electronics | D12: =SUMIF('RETAIL SALES DATA.'!$C$2:$C$1001,Findings!B12,'RETAIL SALES DATA.'!$H$2:$H$1001) -> 2194736.6 | E12: =COUNTIF('RETAIL SALES DATA.'!$C$2:$C$1001,Findings!B12) -> 73 | F12: =SUMIFS('RETAIL SALES DATA.'!$I$2:$I$1001,'RETAIL SALES DATA.'!$C$2:$C$1001,Findings!B12) -> 1510910.9 | G12: =SUMIFS('RETAIL SALES DATA.'!$J$2:$J$1001,'RETAIL SALES DATA.'!$C$2:$C$1001,Findings!B12) -> 683825.7 | H12: =AVERAGEIF('RETAIL SALES DATA.'!$C$2:$C$1001,Findings!B12,'RETAIL SALES DATA.'!$H$2:$H$1001) -> 30064.885 | I12: =AVERAGEIF('RETAIL SALES DATA.'!$C$2:$C$1001,Findings!B12,'RETAIL SALES DATA.'!$J$2:$J$1001) -> 9367.4753 | J12: =AVERAGEIF('RETAIL SALES DATA.'!$C$2:$C$1001,Findings!B12,'RETAIL SALES DATA.'!$F$2:$F$1001) -> 11.39726 | L12: Max | M12: =MAX(M8:M11) -> 2785048.3 | N12: =MAX(N8:N11) -> 2785048.3 | O12: =MAX(O8:O11) -> 2536765.1
B13: Sofa | C13: Furniture | D13: =SUMIF('RETAIL SALES DATA.'!$C$2:$C$1001,Findings!B13,'RETAIL SALES DATA.'!$H$2:$H$1001) -> 1590407.2 | E13: =COUNTIF('RETAIL SALES DATA.'!$C$2:$C$1001,Findings!B13) -> 65 | F13: =SUMIFS('RETAIL SALES DATA.'!$I$2:$I$1001,'RETAIL SALES DATA.'!$C$2:$C$1001,Findings!B13) -> 1087252.4 | G13: =SUMIFS('RETAIL SALES DATA.'!$J$2:$J$1001,'RETAIL SALES DATA.'!$C$2:$C$1001,Findings!B13) -> 503154.81 | H13: =AVERAGEIF('RETAIL SALES DATA.'!$C$2:$C$1001,Findings!B13,'RETAIL SALES DATA.'!$H$2:$H$1001) -> 24467.803 | I13: =AVERAGEIF('RETAIL SALES DATA.'!$C$2:$C$1001,Findings!B13,'RETAIL SALES DATA.'!$J$2:$J$1001) -> 7740.8432 | J13: =AVERAGEIF('RETAIL SALES DATA.'!$C$2:$C$1001,Findings!B13,'RETAIL SALES DATA.'!$F$2:$F$1001) -> 10.661538 | L13: Min | M13: =MIN(M8:M12) -> 1770495.3 | N13: =MIN(N8:N11) -> 2077898.5 | O13: =MIN(O8:O10) -> 1750133
B14: File | C14: Office Supplies | D14: =SUMIF('RETAIL SALES DATA.'!$C$2:$C$1001,Findings!B14,'RETAIL SALES DATA.'!$H$2:$H$1001) -> 1996929 | E14: =COUNTIF('RETAIL SALES DATA.'!$C$2:$C$1001,Findings!B14) -> 65 | F14: =SUMIFS('RETAIL SALES DATA.'!$I$2:$I$1001,'RETAIL SALES DATA.'!$C$2:$C$1001,Findings!B14) -> 1352865.8 | G14: =SUMIFS('RETAIL SALES DATA.'!$J$2:$J$1001,'RETAIL SALES DATA.'!$C$2:$C$1001,Findings!B14) -> 644063.19 | H14: =AVERAGEIF('RETAIL SALES DATA.'!$C$2:$C$1001,Findings!B14,'RETAIL SALES DATA.'!$H$2:$H$1001) -> 30721.984 | I14: =AVERAGEIF('RETAIL SALES DATA.'!$C$2:$C$1001,Findings!B14,'RETAIL SALES DATA.'!$J$2:$J$1001) -> 9908.6645 | J14: =AVERAGEIF('RETAIL SALES DATA.'!$C$2:$C$1001,Findings!B14,'RETAIL SALES DATA.'!$F$2:$F$1001) -> 11.8 | L14: Overall Max sales is in West Region for Furniture | P14: Overall Max | Q14: Overall Min
B15: Keyboard | C15: Electronics | D15: =SUMIF('RETAIL SALES DATA.'!$C$2:$C$1001,Findings!B15,'RETAIL SALES DATA.'!$H$2:$H$1001) -> 1747834.5 | E15: =COUNTIF('RETAIL SALES DATA.'!$C$2:$C$1001,Findings!B15) -> 67 | F15: =SUMIFS('RETAIL SALES DATA.'!$I$2:$I$1001,'RETAIL SALES DATA.'!$C$2:$C$1001,Findings!B15) -> 1232029.4 | G15: =SUMIFS('RETAIL SALES DATA.'!$J$2:$J$1001,'RETAIL SALES DATA.'!$C$2:$C$1001,Findings!B15) -> 515805.1 | H15: =AVERAGEIF('RETAIL SALES DATA.'!$C$2:$C$1001,Findings!B15,'RETAIL SALES DATA.'!$H$2:$H$1001) -> 26087.082 | I15: =AVERAGEIF('RETAIL SALES DATA.'!$C$2:$C$1001,Findings!B15,'RETAIL SALES DATA.'!$J$2:$J$1001) -> 7698.5836 | J15: =AVERAGEIF('RETAIL SALES DATA.'!$C$2:$C$1001,Findings!B15,'RETAIL SALES DATA.'!$F$2:$F$1001) -> 10.014925 | L15: Overall Min sales is in East Region for Office Supplies | P15: =MAX(L8:N11) -> 2785048.3 | Q15: =MIN(M8:O11) -> 1750133
B16: Monitor | C16: Electronics | D16: =SUMIF('RETAIL SALES DATA.'!$C$2:$C$1001,Findings!B16,'RETAIL SALES DATA.'!$H$2:$H$1001) -> 1563522.5 | E16: =COUNTIF('RETAIL SALES DATA.'!$C$2:$C$1001,Findings!B16) -> 65 | F16: =SUMIFS('RETAIL SALES DATA.'!$I$2:$I$1001,'RETAIL SALES DATA.'!$C$2:$C$1001,Findings!B16) -> 1059673.5 | G16: =SUMIFS('RETAIL SALES DATA.'!$J$2:$J$1001,'RETAIL SALES DATA.'!$C$2:$C$1001,Findings!B16) -> 503849 | H16: =AVERAGEIF('RETAIL SALES DATA.'!$C$2:$C$1001,Findings!B16,'RETAIL SALES DATA.'!$H$2:$H$1001) -> 24054.192 | I16: =AVERAGEIF('RETAIL SALES DATA.'!$C$2:$C$1001,Findings!B16,'RETAIL SALES DATA.'!$J$2:$J$1001) -> 7751.5231 | J16: =AVERAGEIF('RETAIL SALES DATA.'!$C$2:$C$1001,Findings!B16,'RETAIL SALES DATA.'!$F$2:$F$1001) -> 10.107692
B17: Smartphone | C17: Electronics | D17: =SUMIF('RETAIL SALES DATA.'!$C$2:$C$1001,Findings!B17,'RETAIL SALES DATA.'!$H$2:$H$1001) -> 1515938.9 | E17: =COUNTIF('RETAIL SALES DATA.'!$C$2:$C$1001,Findings!B17) -> 58 | F17: =SUMIFS('RETAIL SALES DATA.'!$I$2:$I$1001,'RETAIL SALES DATA.'!$C$2:$C$1001,Findings!B17) -> 1044138.4 | G17: =SUMIFS('RETAIL SALES DATA.'!$J$2:$J$1001,'RETAIL SALES DATA.'!$C$2:$C$1001,Findings!B17) -> 471800.53 | H17: =AVERAGEIF('RETAIL SALES DATA.'!$C$2:$C$1001,Findings!B17,'RETAIL SALES DATA.'!$H$2:$H$1001) -> 26136.878 | I17: =AVERAGEIF('RETAIL SALES DATA.'!$C$2:$C$1001,Findings!B17,'RETAIL SALES DATA.'!$J$2:$J$1001) -> 8134.4919 | J17: =AVERAGEIF('RETAIL SALES DATA.'!$C$2:$C$1001,Findings!B17,'RETAIL SALES DATA.'!$F$2:$F$1001) -> 10.396552
C19: Total | D19: =SUM(D3:D17) -> 26471144 | E19: =SUM(E3:E17) -> 1000 | F19: =SUM(F3:F17) -> 18267012 | G19: =SUM(G3:G17) -> 8204131.4
B22: Product Category | C22: Question | D22: Answers | F22: Product Category | G22: Max | H22: Min | L22: Most Sold Item West | O22: Less Sold Item East
C23: Avg Sales | D23: =AVERAGEIF('RETAIL SALES DATA.'!$D$2:$D$1001,'RETAIL SALES DATA.'!D977,'RETAIL SALES DATA.'!$H$2:$H$1001) -> 27809.83 | L23: {=_xlfn.UNIQUE('RETAIL SALES DATA.'!$C$2:$C$1001)} -> Pen | M23: =SUMIFS('RETAIL SALES DATA.'!$F$2:$F$1001,'RETAIL SALES DATA.'!$C$2:$C$1001,Findings!L23,'RETAIL SALES DATA.'!$E$2:$E$1001,'RETAIL SALES DATA.'!$E$4) -> 216 | O23: {=_xlfn.UNIQUE('RETAIL SALES DATA.'!$C$2:$C$1001)} -> Pen | P23: =SUMIFS('RETAIL SALES DATA.'!$F$2:$F$1001,'RETAIL SALES DATA.'!$C$2:$C$1001,Findings!O23,'RETAIL SALES DATA.'!$E$2:$E$1001,'RETAIL SALES DATA.'!$E$6) -> 101
B24: Office Supplies | C24: Avg Profit | D24: =AVERAGEIF('RETAIL SALES DATA.'!$D$2:$D$1001,'RETAIL SALES DATA.'!D2,'RETAIL SALES DATA.'!$J$2:$J$1001) -> 8630.1688 | F24: Office Supplies | G24: =_xlfn.MAXIFS('RETAIL SALES DATA.'!$J$2:$J$1001,'RETAIL SALES DATA.'!D2:D1001,'RETAIL SALES DATA.'!D2) -> 40635.02 | H24: =_xlfn.MINIFS('RETAIL SALES DATA.'!$J$2:$J$1001,'RETAIL SALES DATA.'!$D$2:$D$1001,'RETAIL SALES DATA.'!D986) -> 10.48 | L24: Desk | M24: =SUMIFS('RETAIL SALES DATA.'!$F$2:$F$1001,'RETAIL SALES DATA.'!$C$2:$C$1001,Findings!L24,'RETAIL SALES DATA.'!$E$2:$E$1001,'RETAIL SALES DATA.'!$E$4) -> 214 | O24: Desk | P24: =SUMIFS('RETAIL SALES DATA.'!$F$2:$F$1001,'RETAIL SALES DATA.'!$C$2:$C$1001,Findings!O24,'RETAIL SALES DATA.'!$E$2:$E$1001,'RETAIL SALES DATA.'!$E$6) -> 201
C25: Avg Qty Sold | D25: =AVERAGEIF('RETAIL SALES DATA.'!$D$2:$D$1001,'RETAIL SALES DATA.'!D2,'RETAIL SALES DATA.'!$F$2:$F$1001) -> 11.044728 | L25: Marker | M25: =SUMIFS('RETAIL SALES DATA.'!$F$2:$F$1001,'RETAIL SALES DATA.'!$C$2:$C$1001,Findings!L25,'RETAIL SALES DATA.'!$E$2:$E$1001,'RETAIL SALES DATA.'!$E$4) -> 171 | O25: Marker | P25: =SUMIFS('RETAIL SALES DATA.'!$F$2:$F$1001,'RETAIL SALES DATA.'!$C$2:$C$1001,Findings!O25,'RETAIL SALES DATA.'!$E$2:$E$1001,'RETAIL SALES DATA.'!$E$6) -> 184
C26: Avg Sales | D26: =AVERAGEIF('RETAIL SALES DATA.'!$D$2:$D$1001,'RETAIL SALES DATA.'!D4,'RETAIL SALES DATA.'!$H$2:$H$1001) -> 26359.78 | F26: Furniture | G26: =_xlfn.MAXIFS('RETAIL SALES DATA.'!$J$2:$J$1001,'RETAIL SALES DATA.'!$D$2:$D$1001,'RETAIL SALES DATA.'!D4) -> 41219.44 | H26: =_xlfn.MINIFS('RETAIL SALES DATA.'!$J$2:$J$1001,'RETAIL SALES DATA.'!$D$2:$D$1001,'RETAIL SALES DATA.'!D988) -> 63.65 | L26: Laptop | M26: =SUMIFS('RETAIL SALES DATA.'!$F$2:$F$1001,'RETAIL SALES DATA.'!$C$2:$C$1001,Findings!L26,'RETAIL SALES DATA.'!$E$2:$E$1001,'RETAIL SALES DATA.'!$E$4) -> 211 | O26: Laptop | P26: =SUMIFS('RETAIL SALES DATA.'!$F$2:$F$1001,'RETAIL SALES DATA.'!$C$2:$C$1001,Findings!O26,'RETAIL SALES DATA.'!$E$2:$E$1001,'RETAIL SALES DATA.'!$E$6) -> 210
B27: Furniture | C27: Avg Profit | D27: =AVERAGEIF('RETAIL SALES DATA.'!$D$2:$D$1001,'RETAIL SALES DATA.'!D4,'RETAIL SALES DATA.'!$J$2:$J$1001) -> 8452.3397 | L27: Mouse | M27: =SUMIFS('RETAIL SALES DATA.'!$F$2:$F$1001,'RETAIL SALES DATA.'!$C$2:$C$1001,Findings!L27,'RETAIL SALES DATA.'!$E$2:$E$1001,'RETAIL SALES DATA.'!$E$4) -> 167 | O27: Mouse | P27: =SUMIFS('RETAIL SALES DATA.'!$F$2:$F$1001,'RETAIL SALES DATA.'!$C$2:$C$1001,Findings!O27,'RETAIL SALES DATA.'!$E$2:$E$1001,'RETAIL SALES DATA.'!$E$6) -> 228
C28: Avg Qty Sold | D28: =AVERAGEIF('RETAIL SALES DATA.'!$D$2:$D$1001,'RETAIL SALES DATA.'!D4,'RETAIL SALES DATA.'!$F$2:$F$1001) -> 10.424929 | F28: Electronics | G28: =_xlfn.MAXIFS('RETAIL SALES DATA.'!$J$2:$J$1001,'RETAIL SALES DATA.'!$D$2:$D$1001,'RETAIL SALES DATA.'!D982) -> 36970.5 | H28: =_xlfn.MINIFS('RETAIL SALES DATA.'!$J$2:$J$1001,'RETAIL SALES DATA.'!$D$2:$D$1001,'RETAIL SALES DATA.'!D990) -> 17.45 | L28: Notebook | M28: =SUMIFS('RETAIL SALES DATA.'!$F$2:$F$1001,'RETAIL SALES DATA.'!$C$2:$C$1001,Findings!L28,'RETAIL SALES DATA.'!$E$2:$E$1001,'RETAIL SALES DATA.'!$E$4) -> 164 | O28: Notebook | P28: =SUMIFS('RETAIL SALES DATA.'!$F$2:$F$1001,'RETAIL SALES DATA.'!$C$2:$C$1001,Findings!O28,'RETAIL SALES DATA.'!$E$2:$E$1001,'RETAIL SALES DATA.'!$E$6) -> 116
C29: Avg Sales | D29: =AVERAGEIF('RETAIL SALES DATA.'!$D$2:$D$1001,'RETAIL SALES DATA.'!D6,'RETAIL SALES DATA.'!$H$2:$H$1001) -> 25334.325 | L29: Table | M29: =SUMIFS('RETAIL SALES DATA.'!$F$2:$F$1001,'RETAIL SALES DATA.'!$C$2:$C$1001,Findings!L29,'RETAIL SALES DATA.'!$E$2:$E$1001,'RETAIL SALES DATA.'!$E$4) -> 220 | O29: Table | P29: =SUMIFS('RETAIL SALES DATA.'!$F$2:$F$1001,'RETAIL SALES DATA.'!$C$2:$C$1001,Findings!O29,'RETAIL SALES DATA.'!$E$2:$E$1001,'RETAIL SALES DATA.'!$E$6) -> 172
B30: Electronics | C30: Avg Profit | D30: =AVERAGEIF('RETAIL SALES DATA.'!$D$2:$D$1001,'RETAIL SALES DATA.'!D7,'RETAIL SALES DATA.'!$J$2:$J$1001) -> 7542.5529 | L30: Chair | M30: =SUMIFS('RETAIL SALES DATA.'!$F$2:$F$1001,'RETAIL SALES DATA.'!$C$2:$C$1001,Findings!L30,'RETAIL SALES DATA.'!$E$2:$E$1001,'RETAIL SALES DATA.'!$E$4) -> 237 | O30: Chair | P30: =SUMIFS('RETAIL SALES DATA.'!$F$2:$F$1001,'RETAIL SALES DATA.'!$C$2:$C$1001,Findings!O30,'RETAIL SALES DATA.'!$E$2:$E$1001,'RETAIL SALES DATA.'!$E$6) -> 149
C31: Avg Qty Sold | D31: =AVERAGEIF('RETAIL SALES DATA.'!$D$2:$D$1001,'RETAIL SALES DATA.'!D7,'RETAIL SALES DATA.'!$F$2:$F$1001) -> 10.086826 | L31: Cupboard | M31: =SUMIFS('RETAIL SALES DATA.'!$F$2:$F$1001,'RETAIL SALES DATA.'!$C$2:$C$1001,Findings!L31,'RETAIL SALES DATA.'!$E$2:$E$1001,'RETAIL SALES DATA.'!$E$4) -> 213 | O31: Cupboard | P31: =SUMIFS('RETAIL SALES DATA.'!$F$2:$F$1001,'RETAIL SALES DATA.'!$C$2:$C$1001,Findings!O31,'RETAIL SALES DATA.'!$E$2:$E$1001,'RETAIL SALES DATA.'!$E$6) -> 229
L32: Printer | M32: =SUMIFS('RETAIL SALES DATA.'!$F$2:$F$1001,'RETAIL SALES DATA.'!$C$2:$C$1001,Findings!L32,'RETAIL SALES DATA.'!$E$2:$E$1001,'RETAIL SALES DATA.'!$E$4) -> 213 | O32: Printer | P32: =SUMIFS('RETAIL SALES DATA.'!$F$2:$F$1001,'RETAIL SALES DATA.'!$C$2:$C$1001,Findings!O32,'RETAIL SALES DATA.'!$E$2:$E$1001,'RETAIL SALES DATA.'!$E$6) -> 176
L33: Sofa | M33: =SUMIFS('RETAIL SALES DATA.'!$F$2:$F$1001,'RETAIL SALES DATA.'!$C$2:$C$1001,Findings!L33,'RETAIL SALES DATA.'!$E$2:$E$1001,'RETAIL SALES DATA.'!$E$4) -> 160 | O33: Sofa | P33: =SUMIFS('RETAIL SALES DATA.'!$F$2:$F$1001,'RETAIL SALES DATA.'!$C$2:$C$1001,Findings!O33,'RETAIL SALES DATA.'!$E$2:$E$1001,'RETAIL SALES DATA.'!$E$6) -> 198
B34: South | C34: =SUMIF('RETAIL SALES DATA.'!$E$2:$E$1001,'RETAIL SALES DATA.'!E2,'RETAIL SALES DATA.'!$H$2:$H$1001) -> 5968196.4 | D34: =SUMIF('RETAIL SALES DATA.'!$E$2:$E$1001,'RETAIL SALES DATA.'!E2,'RETAIL SALES DATA.'!$J$2:$J$1001) -> 1810833.8 | F34: South | G34: =COUNTIF('RETAIL SALES DATA.'!$E$2:$E$1001,'RETAIL SALES DATA.'!E2) -> 230 | I34: Office Supplies | J34: =COUNTIF('RETAIL SALES DATA.'!$D$2:$D$1001,'RETAIL SALES DATA.'!D2) -> 313 | L34: File | M34: =SUMIFS('RETAIL SALES DATA.'!$F$2:$F$1001,'RETAIL SALES DATA.'!$C$2:$C$1001,Findings!L34,'RETAIL SALES DATA.'!$E$2:$E$1001,'RETAIL SALES DATA.'!$E$4) -> 195 | O34: File | P34: =SUMIFS('RETAIL SALES DATA.'!$F$2:$F$1001,'RETAIL SALES DATA.'!$C$2:$C$1001,Findings!O34,'RETAIL SALES DATA.'!$E$2:$E$1001,'RETAIL SALES DATA.'!$E$6) -> 138
B35: North | C35: =SUMIF('RETAIL SALES DATA.'!$E$2:$E$1001,'RETAIL SALES DATA.'!E3,'RETAIL SALES DATA.'!$H$2:$H$1001) -> 6653980.9 | D35: =SUMIF('RETAIL SALES DATA.'!$E$2:$E$1001,'RETAIL SALES DATA.'!E3,'RETAIL SALES DATA.'!$J$2:$J$1002) -> 1996841.3 | F35: North | G35: =COUNTIF('RETAIL SALES DATA.'!$E$3:$E$1002,'RETAIL SALES DATA.'!E3) -> 251 | I35: Furniture | J35: =COUNTIF('RETAIL SALES DATA.'!$D$2:$D$1002,'RETAIL SALES DATA.'!D4) -> 353 | L35: Keyboard | M35: =SUMIFS('RETAIL SALES DATA.'!$F$2:$F$1001,'RETAIL SALES DATA.'!$C$2:$C$1001,Findings!L35,'RETAIL SALES DATA.'!$E$2:$E$1001,'RETAIL SALES DATA.'!$E$4) -> 189 | O35: Keyboard | P35: =SUMIFS('RETAIL SALES DATA.'!$F$2:$F$1001,'RETAIL SALES DATA.'!$C$2:$C$1001,Findings!O35,'RETAIL SALES DATA.'!$E$2:$E$1001,'RETAIL SALES DATA.'!$E$6) -> 143
B36: West | C36: =SUMIF('RETAIL SALES DATA.'!$E$2:$E$1001,'RETAIL SALES DATA.'!E4,'RETAIL SALES DATA.'!$H$2:$H$1001) -> 7688782.6 | D36: =SUMIF('RETAIL SALES DATA.'!$E$2:$E$1001,'RETAIL SALES DATA.'!E4,'RETAIL SALES DATA.'!$J$2:$J$1001) -> 2558094.4 | F36: West | G36: =COUNTIF('RETAIL SALES DATA.'!$E$4:$E$1003,'RETAIL SALES DATA.'!E4) -> 282 | I36: Electronics | J36: =COUNTIF('RETAIL SALES DATA.'!$D$2:$D$1003,'RETAIL SALES DATA.'!D6) -> 334 | L36: Monitor | M36: =SUMIFS('RETAIL SALES DATA.'!$F$2:$F$1001,'RETAIL SALES DATA.'!$C$2:$C$1001,Findings!L36,'RETAIL SALES DATA.'!$E$2:$E$1001,'RETAIL SALES DATA.'!$E$4) -> 183 | O36: Monitor | P36: =SUMIFS('RETAIL SALES DATA.'!$F$2:$F$1001,'RETAIL SALES DATA.'!$C$2:$C$1001,Findings!O36,'RETAIL SALES DATA.'!$E$2:$E$1001,'RETAIL SALES DATA.'!$E$6) -> 133
B37: East | C37: =SUMIF('RETAIL SALES DATA.'!$E$2:$E$1001,'RETAIL SALES DATA.'!E6,'RETAIL SALES DATA.'!$H$2:$H$1001) -> 6160183.7 | D37: =SUMIF('RETAIL SALES DATA.'!$E$5:$E$1001,'RETAIL SALES DATA.'!E6,'RETAIL SALES DATA.'!$J$5:$J$1001) -> 1838361.8 | F37: East | G37: =COUNTIF('RETAIL SALES DATA.'!$E$5:$E$1004,'RETAIL SALES DATA.'!E5) -> 250 | L37: Smartphone | M37: =SUMIFS('RETAIL SALES DATA.'!$F$2:$F$1001,'RETAIL SALES DATA.'!$C$2:$C$1001,Findings!L37,'RETAIL SALES DATA.'!$E$2:$E$1001,'RETAIL SALES DATA.'!$E$4) -> 171 | O37: Smartphone | P37: =SUMIFS('RETAIL SALES DATA.'!$F$2:$F$1001,'RETAIL SALES DATA.'!$C$2:$C$1001,Findings!O37,'RETAIL SALES DATA.'!$E$2:$E$1001,'RETAIL SALES DATA.'!$E$6) -> 161
L38: MAX | M38: =MAX(M23:M37) -> 237 | O38: MIN | P38: =MIN(P23:P37) -> 101

Sheet Custom
A1: Customers | B1: Trim() | C1: Proper() | D1: Qutantity Purchased
A2: {=_xlfn.UNIQUE('RETAIL SALES DATA.'!$B$2:$B$1001)} -> Michael Winters | B2: {=TRIM(_xlfn.ANCHORARRAY($A$2))} -> Michael Winters | C2: {=PROPER(_xlfn.ANCHORARRAY($B$2))} -> Michael Winters | D2: =SUMIFS('RETAIL SALES DATA.'!$F$2:$F$1001,'RETAIL SALES DATA.'!$B$2:$B$1001,Custom!A2) -> 4
A3: James Olson | B3: James Olson | C3: James Olson | D3: =SUMIFS('RETAIL SALES DATA.'!$F$2:$F$1001,'RETAIL SALES DATA.'!$B$2:$B$1001,Custom!A3) -> 18
A4: Brittney Simmons | B4: Brittney Simmons | C4: Brittney Simmons | D4: =SUMIFS('RETAIL SALES DATA.'!$F$2:$F$1001,'RETAIL SALES DATA.'!$B$2:$B$1001,Custom!A4) -> 18
A5: Courtney Park | B5: Courtney Park | C5: Courtney Park | D5: =SUMIFS('RETAIL SALES DATA.'!$F$2:$F$1001,'RETAIL SALES DATA.'!$B$2:$B$1001,Custom!A5) -> 1
A6: Chloe Villa | B6: Chloe Villa | C6: Chloe Villa | D6: =SUMIFS('RETAIL SALES DATA.'!$F$2:$F$1001,'RETAIL SALES DATA.'!$B$2:$B$1001,Custom!A6) -> 13
A7: Erin Ross | B7: Erin Ross | C7: Erin Ross | D7: =SUMIFS('RETAIL SALES DATA.'!$F$2:$F$1001,'RETAIL SALES DATA.'!$B$2:$B$1001,Custom!A7) -> 1
A8: Ryan Brown | B8: Ryan Brown | C8: Ryan Brown | D8: =SUMIFS('RETAIL SALES DATA.'!$F$2:$F$1001,'RETAIL SALES DATA.'!$B$2:$B$1001,Custom!A8) -> 17
A9: Keith Winters | B9: Keith Winters | C9: Keith Winters | D9: =SUMIFS('RETAIL SALES DATA.'!$F$2:$F$1001,'RETAIL SALES DATA.'!$B$2:$B$1001,Custom!A9) -> 12
A10: Richard Payne | B10: Richard Payne | C10: Richard Payne | D10: =SUMIFS('RETAIL SALES DATA.'!$F$2:$F$1001,'RETAIL SALES DATA.'!$B$2:$B$1001,Custom!A10) -> 2
A11: Cory Roberson | B11: Cory Roberson | C11: Cory Roberson | D11: =SUMIFS('RETAIL SALES DATA.'!$F$2:$F$1001,'RETAIL SALES DATA.'!$B$2:$B$1001,Custom!A11) -> 14
A12: Amanda Cox | B12: Amanda Cox | C12: Amanda Cox | D12: =SUMIFS('RETAIL SALES DATA.'!$F$2:$F$1001,'RETAIL SALES DATA.'!$B$2:$B$1001,Custom!A12) -> 15
A13: Joseph Allison | B13: Joseph Allison | C13: Joseph Allison | D13: =SUMIFS('RETAIL SALES DATA.'!$F$2:$F$1001,'RETAIL SALES DATA.'!$B$2:$B$1001,Custom!A13) -> 12
A14: Sarah Hernandez | B14: Sarah Hernandez | C14: Sarah Hernandez | D14: =SUMIFS('RETAIL SALES DATA.'!$F$2:$F$1001,'RETAIL SALES DATA.'!$B$2:$B$1001,Custom!A14) -> 10
... A993: Matthew Bradley | B993: Matthew Bradley | C993: Matthew Bradley | D993: =SUMIFS('RETAIL SALES DATA.'!$F$2:$F$1001,'RETAIL SALES DATA.'!$B$2:$B$1001,Custom!A993) -> 16
D994: =SUM(D2:D993) -> 10506

Sheet South
A1: SOUTH
A2: Products | B2: Total Quantity | C2: Total Sales | D2: Total Profit | G2: * Max Quantity sold in South region is Printer
A3: {=_xlfn.UNIQUE('RETAIL SALES DATA.'!C2:C1001)} -> Pen | B3: =SUMIFS('RETAIL SALES DATA.'!$F$2:$F$1001,'RETAIL SALES DATA.'!$C$2:$C$1001,South!A3,'RETAIL SALES DATA.'!$E$2:$E$1001,'RETAIL SALES DATA.'!$E$2) -> 79 | C3: =SUMIFS('RETAIL SALES DATA.'!$H$2:$H$1001,'RETAIL SALES DATA.'!$C$2:$C$1001,South!A3,'RETAIL SALES DATA.'!$E$2:$E$1001,'RETAIL SALES DATA.'!$E$2) -> 195480.62 | D3: =SUMIFS('RETAIL SALES DATA.'!$J$2:$J$1001,'RETAIL SALES DATA.'!$C$2:$C$1001,South!A3,'RETAIL SALES DATA.'!$E$2:$E$1001,'RETAIL SALES DATA.'!$E$2) -> 62673.51 | G3: * Min Quantity sold in South region is Pen
A4: Desk | B4: =SUMIFS('RETAIL SALES DATA.'!$F$2:$F$1001,'RETAIL SALES DATA.'!$C$2:$C$1001,South!A4,'RETAIL SALES DATA.'!$E$2:$E$1001,'RETAIL SALES DATA.'!$E$2) -> 188 | C4: =SUMIFS('RETAIL SALES DATA.'!$H$2:$H$1001,'RETAIL SALES DATA.'!$C$2:$C$1001,South!A4,'RETAIL SALES DATA.'!$E$2:$E$1001,'RETAIL SALES DATA.'!$E$2) -> 480597.16 | D4: =SUMIFS('RETAIL SALES DATA.'!$J$2:$J$1001,'RETAIL SALES DATA.'!$C$2:$C$1001,South!A4,'RETAIL SALES DATA.'!$E$2:$E$1001,'RETAIL SALES DATA.'!$E$2) -> 127554.07
A5: Marker | B5: =SUMIFS('RETAIL SALES DATA.'!$F$2:$F$1001,'RETAIL SALES DATA.'!$C$2:$C$1001,South!A5,'RETAIL SALES DATA.'!$E$2:$E$1001,'RETAIL SALES DATA.'!$E$2) -> 99 | C5: =SUMIFS('RETAIL SALES DATA.'!$H$2:$H$1001,'RETAIL SALES DATA.'!$C$2:$C$1001,South!A5,'RETAIL SALES DATA.'!$E$2:$E$1001,'RETAIL SALES DATA.'!$E$2) -> 318100.03 | D5: =SUMIFS('RETAIL SALES DATA.'!$J$2:$J$1001,'RETAIL SALES DATA.'!$C$2:$C$1001,South!A5,'RETAIL SALES DATA.'!$E$2:$E$1001,'RETAIL SALES DATA.'!$E$2) -> 87110.27
A6: Laptop | B6: =SUMIFS('RETAIL SALES DATA.'!$F$2:$F$1001,'RETAIL SALES DATA.'!$C$2:$C$1001,South!A6,'RETAIL SALES DATA.'!$E$2:$E$1001,'RETAIL SALES DATA.'!$E$2) -> 101 | C6: =SUMIFS('RETAIL SALES DATA.'!$H$2:$H$1001,'RETAIL SALES DATA.'!$C$2:$C$1001,South!A6,'RETAIL SALES DATA.'!$E$2:$E$1001,'RETAIL SALES DATA.'!$E$2) -> 312560.07 | D6: =SUMIFS('RETAIL SALES DATA.'!$J$2:$J$1001,'RETAIL SALES DATA.'!$C$2:$C$1001,South!A6,'RETAIL SALES DATA.'!$E$2:$E$1001,'RETAIL SALES DATA.'!$E$2) -> 82929.89
A7: Mouse | B7: =SUMIFS('RETAIL SALES DATA.'!$F$2:$F$1001,'RETAIL SALES DATA.'!$C$2:$C$1001,South!A7,'RETAIL SALES DATA.'!$E$2:$E$1001,'RETAIL SALES DATA.'!$E$2) -> 147 | C7: =SUMIFS('RETAIL SALES DATA.'!$H$2:$H$1001,'RETAIL SALES DATA.'!$C$2:$C$1001,South!A7,'RETAIL SALES DATA.'!$E$2:$E$1001,'RETAIL SALES DATA.'!$E$2) -> 296237.18 | D7: =SUMIFS('RETAIL SALES DATA.'!$J$2:$J$1001,'RETAIL SALES DATA.'!$C$2:$C$1001,South!A7,'RETAIL SALES DATA.'!$E$2:$E$1001,'RETAIL SALES DATA.'!$E$2) -> 76948.04
A8: Notebook | B8: =SUMIFS('RETAIL SALES DATA.'!$F$2:$F$1001,'RETAIL SALES DATA.'!$C$2:$C$1001,South!A8,'RETAIL SALES DATA.'!$E$2:$E$1001,'RETAIL SALES DATA.'!$E$2) -> 137 | C8: =SUMIFS('RETAIL SALES DATA.'!$H$2:$H$1001,'RETAIL SALES DATA.'!$C$2:$C$1001,South!A8,'RETAIL SALES DATA.'!$E$2:$E$1001,'RETAIL SALES DATA.'!$E$2) -> 274635.88 | D8: =SUMIFS('RETAIL SALES DATA.'!$J$2:$J$1001,'RETAIL SALES DATA.'!$C$2:$C$1001,South!A8,'RETAIL SALES DATA.'!$E$2:$E$1001,'RETAIL SALES DATA.'!$E$2) -> 77950.75
A9: Table | B9: =SUMIFS('RETAIL SALES DATA.'!$F$2:$F$1001,'RETAIL SALES DATA.'!$C$2:$C$1001,South!A9,'RETAIL SALES DATA.'!$E$2:$E$1001,'RETAIL SALES DATA.'!$E$2) -> 127 | C9: =SUMIFS('RETAIL SALES DATA.'!$H$2:$H$1001,'RETAIL SALES DATA.'!$C$2:$C$1001,South!A9,'RETAIL SALES DATA.'!$E$2:$E$1001,'RETAIL SALES DATA.'!$E$2) -> 392182.83 | D9: =SUMIFS('RETAIL SALES DATA.'!$J$2:$J$1001,'RETAIL SALES DATA.'!$C$2:$C$1001,South!A9,'RETAIL SALES DATA.'!$E$2:$E$1001,'RETAIL SALES DATA.'!$E$2) -> 158572.8
A10: Chair | B10: =SUMIFS('RETAIL SALES DATA.'!$F$2:$F$1001,'RETAIL SALES DATA.'!$C$2:$C$1001,South!A10,'RETAIL SALES DATA.'!$E$2:$E$1001,'RETAIL SALES DATA.'!$E$2) -> 245 | C10: =SUMIFS('RETAIL SALES DATA.'!$H$2:$H$1001,'RETAIL SALES DATA.'!$C$2:$C$1001,South!A10,'RETAIL SALES DATA.'!$E$2:$E$1001,'RETAIL SALES DATA.'!$E$2) -> 486506.94 | D10: =SUMIFS('RETAIL SALES DATA.'!$J$2:$J$1001,'RETAIL SALES DATA.'!$C$2:$C$1001,South!A10,'RETAIL SALES DATA.'!$E$2:$E$1001,'RETAIL SALES DATA.'!$E$2) -> 135334.79
A11: Cupboard | B11: =SUMIFS('RETAIL SALES DATA.'!$F$2:$F$1001,'RETAIL SALES DATA.'!$C$2:$C$1001,South!A11,'RETAIL SALES DATA.'!$E$2:$E$1001,'RETAIL SALES DATA.'!$E$2) -> 85 | C11: =SUMIFS('RETAIL SALES DATA.'!$H$2:$H$1001,'RETAIL SALES DATA.'!$C$2:$C$1001,South!A11,'RETAIL SALES DATA.'!$E$2:$E$1001,'RETAIL SALES DATA.'!$E$2) -> 272720.92 | D11: =SUMIFS('RETAIL SALES DATA.'!$J$2:$J$1001,'RETAIL SALES DATA.'!$C$2:$C$1001,South!A11,'RETAIL SALES DATA.'!$E$2:$E$1001,'RETAIL SALES DATA.'!$E$2) -> 66461.43
A12: Printer | B12: =SUMIFS('RETAIL SALES DATA.'!$F$2:$F$1001,'RETAIL SALES DATA.'!$C$2:$C$1001,South!A12,'RETAIL SALES DATA.'!$E$2:$E$1001,'RETAIL SALES DATA.'!$E$2) -> 247 | C12: =SUMIFS('RETAIL SALES DATA.'!$H$2:$H$1001,'RETAIL SALES DATA.'!$C$2:$C$1001,South!A12,'RETAIL SALES DATA.'!$E$2:$E$1001,'RETAIL SALES DATA.'!$E$2) -> 707701.9 | D12: =SUMIFS('RETAIL SALES DATA.'!$J$2:$J$1001,'RETAIL SALES DATA.'!$C$2:$C$1001,South!A12,'RETAIL SALES DATA.'!$E$2:$E$1001,'RETAIL SALES DATA.'!$E$2) -> 221977.88
A13: Sofa | B13: =SUMIFS('RETAIL SALES DATA.'!$F$2:$F$1001,'RETAIL SALES DATA.'!$C$2:$C$1001,South!A13,'RETAIL SALES DATA.'!$E$2:$E$1001,'RETAIL SALES DATA.'!$E$2) -> 205 | C13: =SUMIFS('RETAIL SALES DATA.'!$H$2:$H$1001,'RETAIL SALES DATA.'!$C$2:$C$1001,South!A13,'RETAIL SALES DATA.'!$E$2:$E$1001,'RETAIL SALES DATA.'!$E$2) -> 445890.62 | D13: =SUMIFS('RETAIL SALES DATA.'!$J$2:$J$1001,'RETAIL SALES DATA.'!$C$2:$C$1001,South!A13,'RETAIL SALES DATA.'!$E$2:$E$1001,'RETAIL SALES DATA.'!$E$2) -> 152464.34
A14: File | B14: =SUMIFS('RETAIL SALES DATA.'!$F$2:$F$1001,'RETAIL SALES DATA.'!$C$2:$C$1001,South!A14,'RETAIL SALES DATA.'!$E$2:$E$1001,'RETAIL SALES DATA.'!$E$2) -> 245 | C14: =SUMIFS('RETAIL SALES DATA.'!$H$2:$H$1001,'RETAIL SALES DATA.'!$C$2:$C$1001,South!A14,'RETAIL SALES DATA.'!$E$2:$E$1001,'RETAIL SALES DATA.'!$E$2) -> 644246.54 | D14: =SUMIFS('RETAIL SALES DATA.'!$J$2:$J$1001,'RETAIL SALES DATA.'!$C$2:$C$1001,South!A14,'RETAIL SALES DATA.'!$E$2:$E$1001,'RETAIL SALES DATA.'!$E$2) -> 199676.17
A15: Keyboard | B15: =SUMIFS('RETAIL SALES DATA.'!$F$2:$F$1001,'RETAIL SALES DATA.'!$C$2:$C$1001,South!A15,'RETAIL SALES DATA.'!$E$2:$E$1001,'RETAIL SALES DATA.'!$E$2) -> 176 | C15: =SUMIFS('RETAIL SALES DATA.'!$H$2:$H$1001,'RETAIL SALES DATA.'!$C$2:$C$1001,South!A15,'RETAIL SALES DATA.'!$E$2:$E$1001,'RETAIL SALES DATA.'!$E$2) -> 415632.9 | D15: =SUMIFS('RETAIL SALES DATA.'!$J$2:$J$1001,'RETAIL SALES DATA.'!$C$2:$C$1001,South!A15,'RETAIL SALES DATA.'!$E$2:$E$1001,'RETAIL SALES DATA.'!$E$2) -> 139084.19
... A17: Smartphone | B17: =SUMIFS('RETAIL SALES DATA.'!$F$2:$F$1001,'RETAIL SALES DATA.'!$C$2:$C$1001,South!A17,'RETAIL SALES DATA.'!$E$2:$E$1001,'RETAIL SALES DATA.'!$E$2) -> 161 | C17: =SUMIFS('RETAIL SALES DATA.'!$H$2:$H$1001,'RETAIL SALES DATA.'!$C$2:$C$1001,South!A17,'RETAIL SALES DATA.'!$E$2:$E$1001,'RETAIL SALES DATA.'!$E$2) -> 313897.08 | D17: =SUMIFS('RETAIL SALES DATA.'!$J$2:$J$1001,'RETAIL SALES DATA.'!$C$2:$C$1001,South!A17,'RETAIL SALES DATA.'!$E$2:$E$1001,'RETAIL SALES DATA.'!$E$2) -> 96260.62
A18: MAX | B18: =MAX(B3:B17) -> 247 | C18: =MAX(C3:C17) -> 707701.9 | D18: =MAX(D3:D17) -> 221977.88
A19: MIN | B19: =MIN(B3:B18) -> 79 | C19: =MIN(C3:C18) -> 195480.62 | D19: =MIN(D3:D18) -> 62673.51

Sheet North
A1: NORTH
A2: Products | B2: Total Quantity | C2: Total Sales | D2: Total Profit | G2: *Max Quantity sold in North region is Desk
A3: {=_xlfn.UNIQUE('RETAIL SALES DATA.'!C2:C1001)} -> Pen | B3: =SUMIFS('RETAIL SALES DATA.'!$F$2:$F$1001,'RETAIL SALES DATA.'!$C$2:$C$1001,North!A3,'RETAIL SALES DATA.'!$E$2:$E$1001,'RETAIL SALES DATA.'!$E$3) -> 237 | C3: =SUMIFS('RETAIL SALES DATA.'!$H$2:$H$1001,'RETAIL SALES DATA.'!$C$2:$C$1001,North!A3,'RETAIL SALES DATA.'!$E$2:$E$1001,'RETAIL SALES DATA.'!$E$3) -> 449510.32 | D3: =SUMIFS('RETAIL SALES DATA.'!$J$2:$J$1001,'RETAIL SALES DATA.'!$C$2:$C$1001,North!A3,'RETAIL SALES DATA.'!$E$2:$E$1001,'RETAIL SALES DATA.'!$E$3) -> 132195.89 | G3: *Min Quantity sold in North region is Smarthphone
A4: Desk | B4: =SUMIFS('RETAIL SALES DATA.'!$F$2:$F$1001,'RETAIL SALES DATA.'!$C$2:$C$1001,North!A4,'RETAIL SALES DATA.'!$E$2:$E$1001,'RETAIL SALES DATA.'!$E$3) -> 256 | C4: =SUMIFS('RETAIL SALES DATA.'!$H$2:$H$1001,'RETAIL SALES DATA.'!$C$2:$C$1001,North!A4,'RETAIL SALES DATA.'!$E$2:$E$1001,'RETAIL SALES DATA.'!$E$3) -> 635807.82 | D4: =SUMIFS('RETAIL SALES DATA.'!$J$2:$J$1001,'RETAIL SALES DATA.'!$C$2:$C$1001,North!A4,'RETAIL SALES DATA.'!$E$2:$E$1001,'RETAIL SALES DATA.'!$E$3) -> 205688.43
A5: Marker | B5: =SUMIFS('RETAIL SALES DATA.'!$F$2:$F$1001,'RETAIL SALES DATA.'!$C$2:$C$1001,North!A5,'RETAIL SALES DATA.'!$E$2:$E$1001,'RETAIL SALES DATA.'!$E$3) -> 136 | C5: =SUMIFS('RETAIL SALES DATA.'!$H$2:$H$1001,'RETAIL SALES DATA.'!$C$2:$C$1001,North!A5,'RETAIL SALES DATA.'!$E$2:$E$1001,'RETAIL SALES DATA.'!$E$3) -> 420564.89 | D5: =SUMIFS('RETAIL SALES DATA.'!$J$2:$J$1001,'RETAIL SALES DATA.'!$C$2:$C$1001,North!A5,'RETAIL SALES DATA.'!$E$2:$E$1001,'RETAIL SALES DATA.'!$E$3) -> 115515.34
A6: Laptop | B6: =SUMIFS('RETAIL SALES DATA.'!$F$2:$F$1001,'RETAIL SALES DATA.'!$C$2:$C$1001,North!A6,'RETAIL SALES DATA.'!$E$2:$E$1001,'RETAIL SALES DATA.'!$E$3) -> 169 | C6: =SUMIFS('RETAIL SALES DATA.'!$H$2:$H$1001,'RETAIL SALES DATA.'!$C$2:$C$1001,North!A6,'RETAIL SALES DATA.'!$E$2:$E$1001,'RETAIL SALES DATA.'!$E$3) -> 473103.68 | D6: =SUMIFS('RETAIL SALES DATA.'!$J$2:$J$1001,'RETAIL SALES DATA.'!$C$2:$C$1001,North!A6,'RETAIL SALES DATA.'!$E$2:$E$1001,'RETAIL SALES DATA.'!$E$3) -> 121036.37
A7: Mouse | B7: =SUMIFS('RETAIL SALES DATA.'!$F$2:$F$1001,'RETAIL SALES DATA.'!$C$2:$C$1001,North!A7,'RETAIL SALES DATA.'!$E$2:$E$1001,'RETAIL SALES DATA.'!$E$3) -> 205 | C7: =SUMIFS('RETAIL SALES DATA.'!$H$2:$H$1001,'RETAIL SALES DATA.'!$C$2:$C$1001,North!A7,'RETAIL SALES DATA.'!$E$2:$E$1001,'RETAIL SALES DATA.'!$E$3) -> 537157.6 | D7: =SUMIFS('RETAIL SALES DATA.'!$J$2:$J$1001,'RETAIL SALES DATA.'!$C$2:$C$1001,North!A7,'RETAIL SALES DATA.'!$E$2:$E$1001,'RETAIL SALES DATA.'!$E$3) -> 161196.67
A8: Notebook | B8: =SUMIFS('RETAIL SALES DATA.'!$F$2:$F$1001,'RETAIL SALES DATA.'!$C$2:$C$1001,North!A8,'RETAIL SALES DATA.'!$E$2:$E$1001,'RETAIL SALES DATA.'!$E$3) -> 218 | C8: =SUMIFS('RETAIL SALES DATA.'!$H$2:$H$1001,'RETAIL SALES DATA.'!$C$2:$C$1001,North!A8,'RETAIL SALES DATA.'!$E$2:$E$1001,'RETAIL SALES DATA.'!$E$3) -> 490517.17 | D8: =SUMIFS('RETAIL SALES DATA.'!$J$2:$J$1001,'RETAIL SALES DATA.'!$C$2:$C$1001,North!A8,'RETAIL SALES DATA.'!$E$2:$E$1001,'RETAIL SALES DATA.'!$E$3) -> 158019.61
A9: Table | B9: =SUMIFS('RETAIL SALES DATA.'!$F$2:$F$1001,'RETAIL SALES DATA.'!$C$2:$C$1001,North!A9,'RETAIL SALES DATA.'!$E$2:$E$1001,'RETAIL SALES DATA.'!$E$3) -> 169 | C9: =SUMIFS('RETAIL SALES DATA.'!$H$2:$H$1001,'RETAIL SALES DATA.'!$C$2:$C$1001,North!A9,'RETAIL SALES DATA.'!$E$2:$E$1001,'RETAIL SALES DATA.'!$E$3) -> 355537.4 | D9: =SUMIFS('RETAIL SALES DATA.'!$J$2:$J$1001,'RETAIL SALES DATA.'!$C$2:$C$1001,North!A9,'RETAIL SALES DATA.'!$E$2:$E$1001,'RETAIL SALES DATA.'!$E$3) -> 111001.13
A10: Chair | B10: =SUMIFS('RETAIL SALES DATA.'!$F$2:$F$1001,'RETAIL SALES DATA.'!$C$2:$C$1001,North!A10,'RETAIL SALES DATA.'!$E$2:$E$1001,'RETAIL SALES DATA.'!$E$3) -> 137 | C10: =SUMIFS('RETAIL SALES DATA.'!$H$2:$H$1001,'RETAIL SALES DATA.'!$C$2:$C$1001,North!A10,'RETAIL SALES DATA.'!$E$2:$E$1001,'RETAIL SALES DATA.'!$E$3) -> 401400.85 | D10: =SUMIFS('RETAIL SALES DATA.'!$J$2:$J$1001,'RETAIL SALES DATA.'!$C$2:$C$1001,North!A10,'RETAIL SALES DATA.'!$E$2:$E$1001,'RETAIL SALES DATA.'!$E$3) -> 136559.66
A11: Cupboard | B11: =SUMIFS('RETAIL SALES DATA.'!$F$2:$F$1001,'RETAIL SALES DATA.'!$C$2:$C$1001,North!A11,'RETAIL SALES DATA.'!$E$2:$E$1001,'RETAIL SALES DATA.'!$E$3) -> 145 | C11: =SUMIFS('RETAIL SALES DATA.'!$H$2:$H$1001,'RETAIL SALES DATA.'!$C$2:$C$1001,North!A11,'RETAIL SALES DATA.'!$E$2:$E$1001,'RETAIL SALES DATA.'!$E$3) -> 457146.23 | D11: =SUMIFS('RETAIL SALES DATA.'!$J$2:$J$1001,'RETAIL SALES DATA.'!$C$2:$C$1001,North!A11,'RETAIL SALES DATA.'!$E$2:$E$1001,'RETAIL SALES DATA.'!$E$3) -> 157077.28
A12: Printer | B12: =SUMIFS('RETAIL SALES DATA.'!$F$2:$F$1001,'RETAIL SALES DATA.'!$C$2:$C$1001,North!A12,'RETAIL SALES DATA.'!$E$2:$E$1001,'RETAIL SALES DATA.'!$E$3) -> 196 | C12: =SUMIFS('RETAIL SALES DATA.'!$H$2:$H$1001,'RETAIL SALES DATA.'!$C$2:$C$1001,North!A12,'RETAIL SALES DATA.'!$E$2:$E$1001,'RETAIL SALES DATA.'!$E$3) -> 494762.62 | D12: =SUMIFS('RETAIL SALES DATA.'!$J$2:$J$1001,'RETAIL SALES DATA.'!$C$2:$C$1001,North!A12,'RETAIL SALES DATA.'!$E$2:$E$1001,'RETAIL SALES DATA.'!$E$3) -> 117083.44
A13: Sofa | B13: =SUMIFS('RETAIL SALES DATA.'!$F$2:$F$1001,'RETAIL SALES DATA.'!$C$2:$C$1001,North!A13,'RETAIL SALES DATA.'!$E$2:$E$1001,'RETAIL SALES DATA.'!$E$3) -> 130 | C13: =SUMIFS('RETAIL SALES DATA.'!$H$2:$H$1001,'RETAIL SALES DATA.'!$C$2:$C$1001,North!A13,'RETAIL SALES DATA.'!$E$2:$E$1001,'RETAIL SALES DATA.'!$E$3) -> 348014.41 | D13: =SUMIFS('RETAIL SALES DATA.'!$J$2:$J$1001,'RETAIL SALES DATA.'!$C$2:$C$1001,North!A13,'RETAIL SALES DATA.'!$E$2:$E$1001,'RETAIL SALES DATA.'!$E$3) -> 115701.15
A14: File | B14: =SUMIFS('RETAIL SALES DATA.'!$F$2:$F$1001,'RETAIL SALES DATA.'!$C$2:$C$1001,North!A14,'RETAIL SALES DATA.'!$E$2:$E$1001,'RETAIL SALES DATA.'!$E$3) -> 189 | C14: =SUMIFS('RETAIL SALES DATA.'!$H$2:$H$1001,'RETAIL SALES DATA.'!$C$2:$C$1001,North!A14,'RETAIL SALES DATA.'!$E$2:$E$1001,'RETAIL SALES DATA.'!$E$3) -> 571492.25 | D14: =SUMIFS('RETAIL SALES DATA.'!$J$2:$J$1001,'RETAIL SALES DATA.'!$C$2:$C$1001,North!A14,'RETAIL SALES DATA.'!$E$2:$E$1001,'RETAIL SALES DATA.'!$E$3) -> 175383.18
A15: Keyboard | B15: =SUMIFS('RETAIL SALES DATA.'!$F$2:$F$1001,'RETAIL SALES DATA.'!$C$2:$C$1001,North!A15,'RETAIL SALES DATA.'!$E$2:$E$1001,'RETAIL SALES DATA.'!$E$3) -> 163 | C15: =SUMIFS('RETAIL SALES DATA.'!$H$2:$H$1001,'RETAIL SALES DATA.'!$C$2:$C$1001,North!A15,'RETAIL SALES DATA.'!$E$2:$E$1001,'RETAIL SALES DATA.'!$E$3) -> 352281.89 | D15: =SUMIFS('RETAIL SALES DATA.'!$J$2:$J$1001,'RETAIL SALES DATA.'!$C$2:$C$1001,North!A15,'RETAIL SALES DATA.'!$E$2:$E$1001,'RETAIL SALES DATA.'!$E$3) -> 101354.63
... A17: Smartphone | B17: =SUMIFS('RETAIL SALES DATA.'!$F$2:$F$1001,'RETAIL SALES DATA.'!$C$2:$C$1001,North!A17,'RETAIL SALES DATA.'!$E$2:$E$1001,'RETAIL SALES DATA.'!$E$3) -> 110 | C17: =SUMIFS('RETAIL SALES DATA.'!$H$2:$H$1001,'RETAIL SALES DATA.'!$C$2:$C$1001,North!A17,'RETAIL SALES DATA.'!$E$2:$E$1001,'RETAIL SALES DATA.'!$E$3) -> 327262.45 | D17: =SUMIFS('RETAIL SALES DATA.'!$J$2:$J$1001,'RETAIL SALES DATA.'!$C$2:$C$1001,North!A17,'RETAIL SALES DATA.'!$E$2:$E$1001,'RETAIL SALES DATA.'!$E$3) -> 79919.79
A18: MAX | B18: =MAX(B3:B17) -> 256 | C18: =MAX(C3:C17) -> 635807.82 | D18: =MAX(D3:D17) -> 205688.43
A19: MIN | B19: =MIN(B3:B17) -> 110 | C19: =MIN(C3:C17) -> 327262.45 | D19: =MIN(D3:D17) -> 79919.79

Sheet West
A1: WEST
A2: Products | B2: Total Quantity | C2: Total Sales | D2: Total Profit | G2: *Max Quantity sold in West region is Chair
A3: {=_xlfn.UNIQUE('RETAIL SALES DATA.'!C2:C1001)} -> Pen | B3: =SUMIFS('RETAIL SALES DATA.'!$F$2:$F$1001,'RETAIL SALES DATA.'!$C$2:$C$1001,West!A3,'RETAIL SALES DATA.'!$E$2:$E$1001,'RETAIL SALES DATA.'!$E$4) -> 216 | C3: =SUMIFS('RETAIL SALES DATA.'!$H$2:$H$1001,'RETAIL SALES DATA.'!$C$2:$C$1001,West!A3,'RETAIL SALES DATA.'!$E$2:$E$1001,'RETAIL SALES DATA.'!$E$4) -> 622147.78 | D3: =SUMIFS('RETAIL SALES DATA.'!$J$2:$J$1001,'RETAIL SALES DATA.'!$C$2:$C$1001,West!A3,'RETAIL SALES DATA.'!$E$2:$E$1001,'RETAIL SALES DATA.'!$E$4) -> 195996.34 | G3: *Min Quantity sold in West region is Sofa
A4: Desk | B4: =SUMIFS('RETAIL SALES DATA.'!$F$2:$F$1001,'RETAIL SALES DATA.'!$C$2:$C$1001,West!A4,'RETAIL SALES DATA.'!$E$2:$E$1001,'RETAIL SALES DATA.'!$E$4) -> 214 | C4: =SUMIFS('RETAIL SALES DATA.'!$H$2:$H$1001,'RETAIL SALES DATA.'!$C$2:$C$1001,West!A4,'RETAIL SALES DATA.'!$E$2:$E$1001,'RETAIL SALES DATA.'!$E$4) -> 556768.77 | D4: =SUMIFS('RETAIL SALES DATA.'!$J$2:$J$1001,'RETAIL SALES DATA.'!$C$2:$C$1001,West!A4,'RETAIL SALES DATA.'!$E$2:$E$1001,'RETAIL SALES DATA.'!$E$4) -> 213073.27
A5: Marker | B5: =SUMIFS('RETAIL SALES DATA.'!$F$2:$F$1001,'RETAIL SALES DATA.'!$C$2:$C$1001,West!A5,'RETAIL SALES DATA.'!$E$2:$E$1001,'RETAIL SALES DATA.'!$E$4) -> 171 | C5: =SUMIFS('RETAIL SALES DATA.'!$H$2:$H$1001,'RETAIL SALES DATA.'!$C$2:$C$1001,West!A5,'RETAIL SALES DATA.'!$E$2:$E$1001,'RETAIL SALES DATA.'!$E$4) -> 342580.15 | D5: =SUMIFS('RETAIL SALES DATA.'!$J$2:$J$1001,'RETAIL SALES DATA.'!$C$2:$C$1001,West!A5,'RETAIL SALES DATA.'!$E$2:$E$1001,'RETAIL SALES DATA.'!$E$4) -> 127258.46
A6: Laptop | B6: =SUMIFS('RETAIL SALES DATA.'!$F$2:$F$1001,'RETAIL SALES DATA.'!$C$2:$C$1001,West!A6,'RETAIL SALES DATA.'!$E$2:$E$1001,'RETAIL SALES DATA.'!$E$4) -> 211 | C6: =SUMIFS('RETAIL SALES DATA.'!$H$2:$H$1001,'RETAIL SALES DATA.'!$C$2:$C$1001,West!A6,'RETAIL SALES DATA.'!$E$2:$E$1001,'RETAIL SALES DATA.'!$E$4) -> 509056.38 | D6: =SUMIFS('RETAIL SALES DATA.'!$J$2:$J$1001,'RETAIL SALES DATA.'!$C$2:$C$1001,West!A6,'RETAIL SALES DATA.'!$E$2:$E$1001,'RETAIL SALES DATA.'!$E$4) -> 177437.25
A7: Mouse | B7: =SUMIFS('RETAIL SALES DATA.'!$F$2:$F$1001,'RETAIL SALES DATA.'!$C$2:$C$1001,West!A7,'RETAIL SALES DATA.'!$E$2:$E$1001,'RETAIL SALES DATA.'!$E$4) -> 167 | C7: =SUMIFS('RETAIL SALES DATA.'!$H$2:$H$1001,'RETAIL SALES DATA.'!$C$2:$C$1001,West!A7,'RETAIL SALES DATA.'!$E$2:$E$1001,'RETAIL SALES DATA.'!$E$4) -> 458244.01 | D7: =SUMIFS('RETAIL SALES DATA.'!$J$2:$J$1001,'RETAIL SALES DATA.'!$C$2:$C$1001,West!A7,'RETAIL SALES DATA.'!$E$2:$E$1001,'RETAIL SALES DATA.'!$E$4) -> 136713.98
A8: Notebook | B8: =SUMIFS('RETAIL SALES DATA.'!$F$2:$F$1001,'RETAIL SALES DATA.'!$C$2:$C$1001,West!A8,'RETAIL SALES DATA.'!$E$2:$E$1001,'RETAIL SALES DATA.'!$E$4) -> 164 | C8: =SUMIFS('RETAIL SALES DATA.'!$H$2:$H$1001,'RETAIL SALES DATA.'!$C$2:$C$1001,West!A8,'RETAIL SALES DATA.'!$E$2:$E$1001,'RETAIL SALES DATA.'!$E$4) -> 443183.14 | D8: =SUMIFS('RETAIL SALES DATA.'!$J$2:$J$1001,'RETAIL SALES DATA.'!$C$2:$C$1001,West!A8,'RETAIL SALES DATA.'!$E$2:$E$1001,'RETAIL SALES DATA.'!$E$4) -> 131113.78
A9: Table | B9: =SUMIFS('RETAIL SALES DATA.'!$F$2:$F$1001,'RETAIL SALES DATA.'!$C$2:$C$1001,West!A9,'RETAIL SALES DATA.'!$E$2:$E$1001,'RETAIL SALES DATA.'!$E$4) -> 220 | C9: =SUMIFS('RETAIL SALES DATA.'!$H$2:$H$1001,'RETAIL SALES DATA.'!$C$2:$C$1001,West!A9,'RETAIL SALES DATA.'!$E$2:$E$1001,'RETAIL SALES DATA.'!$E$4) -> 538064.13 | D9: =SUMIFS('RETAIL SALES DATA.'!$J$2:$J$1001,'RETAIL SALES DATA.'!$C$2:$C$1001,West!A9,'RETAIL SALES DATA.'!$E$2:$E$1001,'RETAIL SALES DATA.'!$E$4) -> 147838.78
A10: Chair | B10: =SUMIFS('RETAIL SALES DATA.'!$F$2:$F$1001,'RETAIL SALES DATA.'!$C$2:$C$1001,West!A10,'RETAIL SALES DATA.'!$E$2:$E$1001,'RETAIL SALES DATA.'!$E$4) -> 237 | C10: =SUMIFS('RETAIL SALES DATA.'!$H$2:$H$1001,'RETAIL SALES DATA.'!$C$2:$C$1001,West!A10,'RETAIL SALES DATA.'!$E$2:$E$1001,'RETAIL SALES DATA.'!$E$4) -> 665870.47 | D10: =SUMIFS('RETAIL SALES DATA.'!$J$2:$J$1001,'RETAIL SALES DATA.'!$C$2:$C$1001,West!A10,'RETAIL SALES DATA.'!$E$2:$E$1001,'RETAIL SALES DATA.'!$E$4) -> 253854.63
A11: Cupboard | B11: =SUMIFS('RETAIL SALES DATA.'!$F$2:$F$1001,'RETAIL SALES DATA.'!$C$2:$C$1001,West!A11,'RETAIL SALES DATA.'!$E$2:$E$1001,'RETAIL SALES DATA.'!$E$4) -> 213 | C11: =SUMIFS('RETAIL SALES DATA.'!$H$2:$H$1001,'RETAIL SALES DATA.'!$C$2:$C$1001,West!A11,'RETAIL SALES DATA.'!$E$2:$E$1001,'RETAIL SALES DATA.'!$E$4) -> 624121.92 | D11: =SUMIFS('RETAIL SALES DATA.'!$J$2:$J$1001,'RETAIL SALES DATA.'!$C$2:$C$1001,West!A11,'RETAIL SALES DATA.'!$E$2:$E$1001,'RETAIL SALES DATA.'!$E$4) -> 192071.49
A12: Printer | B12: =SUMIFS('RETAIL SALES DATA.'!$F$2:$F$1001,'RETAIL SALES DATA.'!$C$2:$C$1001,West!A12,'RETAIL SALES DATA.'!$E$2:$E$1001,'RETAIL SALES DATA.'!$E$4) -> 213 | C12: =SUMIFS('RETAIL SALES DATA.'!$H$2:$H$1001,'RETAIL SALES DATA.'!$C$2:$C$1001,West!A12,'RETAIL SALES DATA.'!$E$2:$E$1001,'RETAIL SALES DATA.'!$E$4) -> 526313.54 | D12: =SUMIFS('RETAIL SALES DATA.'!$J$2:$J$1001,'RETAIL SALES DATA.'!$C$2:$C$1001,West!A12,'RETAIL SALES DATA.'!$E$2:$E$1001,'RETAIL SALES DATA.'!$E$4) -> 177243.05
A13: Sofa | B13: =SUMIFS('RETAIL SALES DATA.'!$F$2:$F$1001,'RETAIL SALES DATA.'!$C$2:$C$1001,West!A13,'RETAIL SALES DATA.'!$E$2:$E$1001,'RETAIL SALES DATA.'!$E$4) -> 160 | C13: =SUMIFS('RETAIL SALES DATA.'!$H$2:$H$1001,'RETAIL SALES DATA.'!$C$2:$C$1001,West!A13,'RETAIL SALES DATA.'!$E$2:$E$1001,'RETAIL SALES DATA.'!$E$4) -> 400222.97 | D13: =SUMIFS('RETAIL SALES DATA.'!$J$2:$J$1001,'RETAIL SALES DATA.'!$C$2:$C$1001,West!A13,'RETAIL SALES DATA.'!$E$2:$E$1001,'RETAIL SALES DATA.'!$E$4) -> 122342.69
A14: File | B14: =SUMIFS('RETAIL SALES DATA.'!$F$2:$F$1001,'RETAIL SALES DATA.'!$C$2:$C$1001,West!A14,'RETAIL SALES DATA.'!$E$2:$E$1001,'RETAIL SALES DATA.'!$E$4) -> 195 | C14: =SUMIFS('RETAIL SALES DATA.'!$H$2:$H$1001,'RETAIL SALES DATA.'!$C$2:$C$1001,West!A14,'RETAIL SALES DATA.'!$E$2:$E$1001,'RETAIL SALES DATA.'!$E$4) -> 432744.58 | D14: =SUMIFS('RETAIL SALES DATA.'!$J$2:$J$1001,'RETAIL SALES DATA.'!$C$2:$C$1001,West!A14,'RETAIL SALES DATA.'!$E$2:$E$1001,'RETAIL SALES DATA.'!$E$4) -> 148810.93
A15: Keyboard | B15: =SUMIFS('RETAIL SALES DATA.'!$F$2:$F$1001,'RETAIL SALES DATA.'!$C$2:$C$1001,West!A15,'RETAIL SALES DATA.'!$E$2:$E$1001,'RETAIL SALES DATA.'!$E$4) -> 189 | C15: =SUMIFS('RETAIL SALES DATA.'!$H$2:$H$1001,'RETAIL SALES DATA.'!$C$2:$C$1001,West!A15,'RETAIL SALES DATA.'!$E$2:$E$1001,'RETAIL SALES DATA.'!$E$4) -> 538098.64 | D15: =SUMIFS('RETAIL SALES DATA.'!$J$2:$J$1001,'RETAIL SALES DATA.'!$C$2:$C$1001,West!A15,'RETAIL SALES DATA.'!$E$2:$E$1001,'RETAIL SALES DATA.'!$E$4) -> 173888.23
... A17: Smartphone | B17: =SUMIFS('RETAIL SALES DATA.'!$F$2:$F$1001,'RETAIL SALES DATA.'!$C$2:$C$1001,West!A17,'RETAIL SALES DATA.'!$E$2:$E$1001,'RETAIL SALES DATA.'!$E$4) -> 171 | C17: =SUMIFS('RETAIL SALES DATA.'!$H$2:$H$1001,'RETAIL SALES DATA.'!$C$2:$C$1001,West!A17,'RETAIL SALES DATA.'!$E$2:$E$1001,'RETAIL SALES DATA.'!$E$4) -> 462700.66 | D17: =SUMIFS('RETAIL SALES DATA.'!$J$2:$J$1001,'RETAIL SALES DATA.'!$C$2:$C$1001,West!A17,'RETAIL SALES DATA.'!$E$2:$E$1001,'RETAIL SALES DATA.'!$E$4) -> 163259.62
A18: MAX | B18: =MAX(B3:B17) -> 237 | C18: =MAX(C3:C17) -> 665870.47 | D18: =MAX(D3:D17) -> 253854.63
A19: MIN | B19: =MIN(B3:B18) -> 160 | C19: =MIN(C3:C18) -> 342580.15 | D19: =MIN(D3:D18) -> 122342.69

Sheet East
A1: EAST
A2: Products | B2: Total Quantity | C2: Total Sales | D2: Total Profit | G2: *Max Quantity sold in East region is Cupboard
A3: {=_xlfn.UNIQUE('RETAIL SALES DATA.'!C2:C1001)} -> Pen | B3: =SUMIFS('RETAIL SALES DATA.'!$F$2:$F$1001,'RETAIL SALES DATA.'!$C$2:$C$1001,East!A3,'RETAIL SALES DATA.'!$E$2:$E$1001,'RETAIL SALES DATA.'!$E$6) -> 101 | C3: =SUMIFS('RETAIL SALES DATA.'!$H$2:$H$1001,'RETAIL SALES DATA.'!$C$2:$C$1001,East!A3,'RETAIL SALES DATA.'!$E$2:$E$1001,'RETAIL SALES DATA.'!$E$6) -> 184497.13 | D3: =SUMIFS('RETAIL SALES DATA.'!$J$2:$J$1001,'RETAIL SALES DATA.'!$C$2:$C$1001,East!A3,'RETAIL SALES DATA.'!$E$2:$E$1001,'RETAIL SALES DATA.'!$E$6) -> 48484.69 | G3: *Min Quantity sold in East region is Pen
A4: Desk | B4: =SUMIFS('RETAIL SALES DATA.'!$F$2:$F$1001,'RETAIL SALES DATA.'!$C$2:$C$1001,East!A4,'RETAIL SALES DATA.'!$E$2:$E$1001,'RETAIL SALES DATA.'!$E$6) -> 201 | C4: =SUMIFS('RETAIL SALES DATA.'!$H$2:$H$1001,'RETAIL SALES DATA.'!$C$2:$C$1001,East!A4,'RETAIL SALES DATA.'!$E$2:$E$1001,'RETAIL SALES DATA.'!$E$6) -> 472653.18 | D4: =SUMIFS('RETAIL SALES DATA.'!$J$2:$J$1001,'RETAIL SALES DATA.'!$C$2:$C$1001,East!A4,'RETAIL SALES DATA.'!$E$2:$E$1001,'RETAIL SALES DATA.'!$E$6) -> 154377.88
A5: Marker | B5: =SUMIFS('RETAIL SALES DATA.'!$F$2:$F$1001,'RETAIL SALES DATA.'!$C$2:$C$1001,East!A5,'RETAIL SALES DATA.'!$E$2:$E$1001,'RETAIL SALES DATA.'!$E$6) -> 184 | C5: =SUMIFS('RETAIL SALES DATA.'!$H$2:$H$1001,'RETAIL SALES DATA.'!$C$2:$C$1001,East!A5,'RETAIL SALES DATA.'!$E$2:$E$1001,'RETAIL SALES DATA.'!$E$6) -> 441134.81 | D5: =SUMIFS('RETAIL SALES DATA.'!$J$2:$J$1001,'RETAIL SALES DATA.'!$C$2:$C$1001,East!A5,'RETAIL SALES DATA.'!$E$2:$E$1001,'RETAIL SALES DATA.'!$E$6) -> 140094.35
A6: Laptop | B6: =SUMIFS('RETAIL SALES DATA.'!$F$2:$F$1001,'RETAIL SALES DATA.'!$C$2:$C$1001,East!A6,'RETAIL SALES DATA.'!$E$2:$E$1001,'RETAIL SALES DATA.'!$E$6) -> 210 | C6: =SUMIFS('RETAIL SALES DATA.'!$H$2:$H$1001,'RETAIL SALES DATA.'!$C$2:$C$1001,East!A6,'RETAIL SALES DATA.'!$E$2:$E$1001,'RETAIL SALES DATA.'!$E$6) -> 481891.19 | D6: =SUMIFS('RETAIL SALES DATA.'!$J$2:$J$1001,'RETAIL SALES DATA.'!$C$2:$C$1001,East!A6,'RETAIL SALES DATA.'!$E$2:$E$1001,'RETAIL SALES DATA.'!$E$6) -> 127669.88
A7: Mouse | B7: =SUMIFS('RETAIL SALES DATA.'!$F$2:$F$1001,'RETAIL SALES DATA.'!$C$2:$C$1001,East!A7,'RETAIL SALES DATA.'!$E$2:$E$1001,'RETAIL SALES DATA.'!$E$6) -> 228 | C7: =SUMIFS('RETAIL SALES DATA.'!$H$2:$H$1001,'RETAIL SALES DATA.'!$C$2:$C$1001,East!A7,'RETAIL SALES DATA.'!$E$2:$E$1001,'RETAIL SALES DATA.'!$E$6) -> 566118.61 | D7: =SUMIFS('RETAIL SALES DATA.'!$J$2:$J$1001,'RETAIL SALES DATA.'!$C$2:$C$1001,East!A7,'RETAIL SALES DATA.'!$E$2:$E$1001,'RETAIL SALES DATA.'!$E$6) -> 143825.97
A8: Notebook | B8: =SUMIFS('RETAIL SALES DATA.'!$F$2:$F$1001,'RETAIL SALES DATA.'!$C$2:$C$1001,East!A8,'RETAIL SALES DATA.'!$E$2:$E$1001,'RETAIL SALES DATA.'!$E$6) -> 116 | C8: =SUMIFS('RETAIL SALES DATA.'!$H$2:$H$1001,'RETAIL SALES DATA.'!$C$2:$C$1001,East!A8,'RETAIL SALES DATA.'!$E$2:$E$1001,'RETAIL SALES DATA.'!$E$6) -> 330459.3 | D8: =SUMIFS('RETAIL SALES DATA.'!$J$2:$J$1001,'RETAIL SALES DATA.'!$C$2:$C$1001,East!A8,'RETAIL SALES DATA.'!$E$2:$E$1001,'RETAIL SALES DATA.'!$E$6) -> 96940.94
A9: Table | B9: =SUMIFS('RETAIL SALES DATA.'!$F$2:$F$1001,'RETAIL SALES DATA.'!$C$2:$C$1001,East!A9,'RETAIL SALES DATA.'!$E$2:$E$1001,'RETAIL SALES DATA.'!$E$6) -> 172 | C9: =SUMIFS('RETAIL SALES DATA.'!$H$2:$H$1001,'RETAIL SALES DATA.'!$C$2:$C$1001,East!A9,'RETAIL SALES DATA.'!$E$2:$E$1001,'RETAIL SALES DATA.'!$E$6) -> 439501.06 | D9: =SUMIFS('RETAIL SALES DATA.'!$J$2:$J$1001,'RETAIL SALES DATA.'!$C$2:$C$1001,East!A9,'RETAIL SALES DATA.'!$E$2:$E$1001,'RETAIL SALES DATA.'!$E$6) -> 126762.29
A10: Chair | B10: =SUMIFS('RETAIL SALES DATA.'!$F$2:$F$1001,'RETAIL SALES DATA.'!$C$2:$C$1001,East!A10,'RETAIL SALES DATA.'!$E$2:$E$1001,'RETAIL SALES DATA.'!$E$6) -> 149 | C10: =SUMIFS('RETAIL SALES DATA.'!$H$2:$H$1001,'RETAIL SALES DATA.'!$C$2:$C$1001,East!A10,'RETAIL SALES DATA.'!$E$2:$E$1001,'RETAIL SALES DATA.'!$E$6) -> 343028.85 | D10: =SUMIFS('RETAIL SALES DATA.'!$J$2:$J$1001,'RETAIL SALES DATA.'!$C$2:$C$1001,East!A10,'RETAIL SALES DATA.'!$E$2:$E$1001,'RETAIL SALES DATA.'!$E$6) -> 111914.91
A11: Cupboard | B11: =SUMIFS('RETAIL SALES DATA.'!$F$2:$F$1001,'RETAIL SALES DATA.'!$C$2:$C$1001,East!A11,'RETAIL SALES DATA.'!$E$2:$E$1001,'RETAIL SALES DATA.'!$E$6) -> 229 | C11: =SUMIFS('RETAIL SALES DATA.'!$H$2:$H$1001,'RETAIL SALES DATA.'!$C$2:$C$1001,East!A11,'RETAIL SALES DATA.'!$E$2:$E$1001,'RETAIL SALES DATA.'!$E$6) -> 592686.53 | D11: =SUMIFS('RETAIL SALES DATA.'!$J$2:$J$1001,'RETAIL SALES DATA.'!$C$2:$C$1001,East!A11,'RETAIL SALES DATA.'!$E$2:$E$1001,'RETAIL SALES DATA.'!$E$6) -> 182378.26
A12: Printer | B12: =SUMIFS('RETAIL SALES DATA.'!$F$2:$F$1001,'RETAIL SALES DATA.'!$C$2:$C$1001,East!A12,'RETAIL SALES DATA.'!$E$2:$E$1001,'RETAIL SALES DATA.'!$E$6) -> 176 | C12: =SUMIFS('RETAIL SALES DATA.'!$H$2:$H$1001,'RETAIL SALES DATA.'!$C$2:$C$1001,East!A12,'RETAIL SALES DATA.'!$E$2:$E$1001,'RETAIL SALES DATA.'!$E$6) -> 465958.51 | D12: =SUMIFS('RETAIL SALES DATA.'!$J$2:$J$1001,'RETAIL SALES DATA.'!$C$2:$C$1001,East!A12,'RETAIL SALES DATA.'!$E$2:$E$1001,'RETAIL SALES DATA.'!$E$6) -> 167521.33
A13: Sofa | B13: =SUMIFS('RETAIL SALES DATA.'!$F$2:$F$1001,'RETAIL SALES DATA.'!$C$2:$C$1001,East!A13,'RETAIL SALES DATA.'!$E$2:$E$1001,'RETAIL SALES DATA.'!$E$6) -> 198 | C13: =SUMIFS('RETAIL SALES DATA.'!$H$2:$H$1001,'RETAIL SALES DATA.'!$C$2:$C$1001,East!A13,'RETAIL SALES DATA.'!$E$2:$E$1001,'RETAIL SALES DATA.'!$E$6) -> 396279.19 | D13: =SUMIFS('RETAIL SALES DATA.'!$J$2:$J$1001,'RETAIL SALES DATA.'!$C$2:$C$1001,East!A13,'RETAIL SALES DATA.'!$E$2:$E$1001,'RETAIL SALES DATA.'!$E$6) -> 112646.63
